Workbook
Name Factors_TK00001: #REF!
Name Factors_TK00002: #REF!
Name Factors_TK00003: #REF!
Name Factors_TK00004: #REF!
Name Factors_TK00005: #REF!
Name Factors_TK00006: #REF!
Name Factors_TK00007: #REF!
Name Factors_TK00008: #REF!
Name Factors_TK00009: #REF!
Name Factors_TK00010: #REF!
Name Factors_TK00011: #REF!
Name Factors_TK00012: #REF!
Name Factors_TK00013: #REF!
Name Factors_TK00014: #REF!
Name Factors_TK00015: #REF!
Name Factors_TK00016: #REF!
Name Factors_TK00017: #REF!
Name Factors_TK00018: #REF!
Name Factors_TK00019: #REF!
Name Factors_TK00020: #REF!
Name Factors_TK00021: #REF!
Name Factors_TK00022: #REF!
Name Factors_TK00023: #REF!
Name Factors_TK00024: #REF!
Name Factors_TK00025: #REF!
Name Factors_TK00026: #REF!
Name Factors_TK00027: #REF!
Name Factors_TK00028: #REF!
Name Factors_TK00029: #REF!
Name Factors_TK00030: #REF!
Name Factors_TK00031: #REF!
Name Factors_TK00032: #REF!
Name Factors_TK00033: #REF!
Name Factors_TK00034: #REF!
Name Factors_TK00035: #REF!
Name Factors_TK00036: #REF!
Name Factors_TK00037: #REF!
Name Factors_TK00038: #REF!
Name Factors_TK00039: #REF!
Name Factors_TK00040: #REF!
Name Factors_TK00041: #REF!
Name Factors_TK00042: #REF!
Name Factors_TK00043: #REF!
Name Factors_TK00044: #REF!
Name Factors_TK00045: #REF!
Name Factors_TK00046: #REF!
Name Factors_TK00047: #REF!
Name Factors_TK00048: #REF!
Name Factors_TK00049: #REF!
Name Factors_TK00050: #REF!
Name Factors_TK00051: #REF!
Name Factors_TK00052: #REF!
Name Factors_TK00053: #REF!
Name Factors_TK00054: #REF!
Name Factors_TK00055: #REF!
Name Factors_TK00056: #REF!
Name Factors_TK00057: #REF!
Name Factors_TK00058: #REF!
Name Factors_TK00059: #REF!
Name Factors_TK00060: #REF!

Sheet Taxepunkter
B1: XX kommuns avfallstaxa – fullständig kalkyl (intäkter)
B2: Matriser expanderas: en rad per (Taxapunkt × Variant). §6: Taxapunkt kompletteras med Avfallskod, UN-nummer blir Variant och Enhet tas från enhetskolumn.
A5: Paragraf | B5: Paragrafnamn | C5: Taxapunkt | D5: Variant | E5: Enhet | F5: Taxakod | G5: Föreslagen Taxa | H5: Taxabeskrivning | I5: Faktor | J5: Aktuellt pris (exkl m) | K5: Föreslaget pris | L5: Antal | M5: Pris kr (inkl.) | N5: Intäkt (kr) exkl
A6: §2 Avgifter och tjänster – en- och tvåbostadshus, fritidshus, verksamhet, lägenhet och anläggning
A7: §2.1 Grundavgifter
A8: §2.1.1 Grundavgifter
A9: §2.1 | B9: Grundavgift | C9: En- och tvåbostadshus | E9: st/år | F9: GRUNDPER | G9: =IF($F9<>"",$F9,IFERROR(_xlfn.XLOOKUP(ROW(),Taxa_Saknas!$H:$H,Taxa_Saknas!$G:$G),"")) -> GRUNDPER | H9: =IF($F9<>"",IFERROR(_xlfn.XLOOKUP($F9,Taxa_från_edp!$B:$B,Taxa_från_edp!C:C),""),"") -> Grundavgift permanentboende | I9: =IF($F9<>"",IFERROR(_xlfn.XLOOKUP($F9,Taxa_från_edp!$B:$B,Taxa_från_edp!G:G),""),"") -> ÅRPR | J9: =IF($F9<>"",IFERROR(_xlfn.XLOOKUP($F9,Taxa_från_edp!$B:$B,Taxa_från_edp!K:K),""),"") -> 1280 | M9: =IFERROR(IF(J9<>"",J9*1.25,IF(K9<>"",K9*1.25,"")),"") -> 1600 | N9: =IFERROR(IF(J9<>"",L9*J9,IF(K9<>"",L9*K9,"")),"") -> 0
A10: §2.1 | B10: Grundavgift | C10: Fritidshus | E10: st/år | F10: GRUNDFRI | G10: =IF($F10<>"",$F10,IFERROR(_xlfn.XLOOKUP(ROW(),Taxa_Saknas!$H:$H,Taxa_Saknas!$G:$G),"")) -> GRUNDFRI | H10: =IF($F10<>"",IFERROR(_xlfn.XLOOKUP($F10,Taxa_från_edp!$B:$B,Taxa_från_edp!C:C),""),"") -> Grundavgift fritidshus | I10: =IF($F10<>"",IFERROR(_xlfn.XLOOKUP($F10,Taxa_från_edp!$B:$B,Taxa_från_edp!G:G),""),"") -> ÅRPR | J10: =IF($F10<>"",IFERROR(_xlfn.XLOOKUP($F10,Taxa_från_edp!$B:$B,Taxa_från_edp!K:K),""),"") -> 1040 | M10: =IFERROR(IF(J10<>"",J10*1.25,IF(K10<>"",K10*1.25,"")),"") -> 1300 | N10: =IFERROR(IF(J10<>"",L10*J10,IF(K10<>"",L10*K10,"")),"") -> 0
A11: §2.1 | B11: Grundavgift | C11: Verksamhet | E11: st/år | F11: GRUNDLÄG | G11: =IF($F11<>"",$F11,IFERROR(_xlfn.XLOOKUP(ROW(),Taxa_Saknas!$H:$H,Taxa_Saknas!$G:$G),"")) -> GRUNDLÄG | H11: =IF($F11<>"",IFERROR(_xlfn.XLOOKUP($F11,Taxa_från_edp!$B:$B,Taxa_från_edp!C:C),""),"") -> Grundavgift, tvåbostadshus | I11: =IF($F11<>"",IFERROR(_xlfn.XLOOKUP($F11,Taxa_från_edp!$B:$B,Taxa_från_edp!G:G),""),"") -> ÅRKV | J11: =IF($F11<>"",IFERROR(_xlfn.XLOOKUP($F11,Taxa_från_edp!$B:$B,Taxa_från_edp!K:K),""),"") -> 680 | M11: =IFERROR(IF(J11<>"",J11*1.25,IF(K11<>"",K11*1.25,"")),"") -> 850 | N11: =IFERROR(IF(J11<>"",L11*J11,IF(K11<>"",L11*K11,"")),"") -> 0
A12: §2.1 | B12: Grundavgift | C12: Lägenhet i flerbostadshus | E12: st/år | F12: GRUNDFLB | G12: =IF($F12<>"",$F12,IFERROR(_xlfn.XLOOKUP(ROW(),Taxa_Saknas!$H:$H,Taxa_Saknas!$G:$G),"")) -> GRUNDFLB | H12: =IF($F12<>"",IFERROR(_xlfn.XLOOKUP($F12,Taxa_från_edp!$B:$B,Taxa_från_edp!C:C),""),"") -> Grundavgift per lägenhet, flerbostadshus | I12: =IF($F12<>"",IFERROR(_xlfn.XLOOKUP($F12,Taxa_från_edp!$B:$B,Taxa_från_edp!G:G),""),"") -> ÅRKV | J12: =IF($F12<>"",IFERROR(_xlfn.XLOOKUP($F12,Taxa_från_edp!$B:$B,Taxa_från_edp!K:K),""),"") -> 562.5 | M12: =IFERROR(IF(J12<>"",J12*1.25,IF(K12<>"",K12*1.25,"")),"") -> 703.125 | N12: =IFERROR(IF(J12<>"",L12*J12,IF(K12<>"",L12*K12,"")),"") -> 0
A13: §2.1 | B13: Grundavgift | C13: Lägenhet för specialändamål | E13: st/år | H13: =IF($F13<>"",IFERROR(_xlfn.XLOOKUP($F13,Taxa_från_edp!$B:$B,Taxa_från_edp!C:C),""),"") | I13: =IF($F13<>"",IFERROR(_xlfn.XLOOKUP($F13,Taxa_från_edp!$B:$B,Taxa_från_edp!G:G),""),"") | J13: =IF($F13<>"",IFERROR(_xlfn.XLOOKUP($F13,Taxa_från_edp!$B:$B,Taxa_från_edp!K:K),""),"") | M13: =IFERROR(IF(J13<>"",J13*1.25,IF(K13<>"",K13*1.25,"")),"") | N13: =IFERROR(IF(J13<>"",L13*J13,IF(K13<>"",L13*K13,"")),"")
A14: §2.1 | B14: Grundavgift | C14: Anläggning | E14: st/år | H14: =IF($F14<>"",IFERROR(_xlfn.XLOOKUP($F14,Taxa_från_edp!$B:$B,Taxa_från_edp!C:C),""),"") | I14: =IF($F14<>"",IFERROR(_xlfn.XLOOKUP($F14,Taxa_från_edp!$B:$B,Taxa_från_edp!G:G),""),"") | J14: =IF($F14<>"",IFERROR(_xlfn.XLOOKUP($F14,Taxa_från_edp!$B:$B,Taxa_från_edp!K:K),""),"") | M14: =IFERROR(IF(J14<>"",J14*1.25,IF(K14<>"",K14*1.25,"")),"") | N14: =IFERROR(IF(J14<>"",L14*J14,IF(K14<>"",L14*K14,"")),"")
A15: §2.1 | B15: Grundavgift | C15: Säsongsbaserad uppställningsplats | E15: st/år | H15: =IF($F15<>"",IFERROR(_xlfn.XLOOKUP($F15,Taxa_från_edp!$B:$B,Taxa_från_edp!C:C),""),"") | I15: =IF($F15<>"",IFERROR(_xlfn.XLOOKUP($F15,Taxa_från_edp!$B:$B,Taxa_från_edp!G:G),""),"") | J15: =IF($F15<>"",IFERROR(_xlfn.XLOOKUP($F15,Taxa_från_edp!$B:$B,Taxa_från_edp!K:K),""),"") | M15: =IFERROR(IF(J15<>"",J15*1.25,IF(K15<>"",K15*1.25,"")),"") | N15: =IFERROR(IF(J15<>"",L15*J15,IF(K15<>"",L15*K15,"")),"")
A16: §2.1 | B16: Grundavgift | C16: Campingstuga/-lägenhet | E16: st/år | H16: =IF($F16<>"",IFERROR(_xlfn.XLOOKUP($F16,Taxa_från_edp!$B:$B,Taxa_från_edp!C:C),""),"") | I16: =IF($F16<>"",IFERROR(_xlfn.XLOOKUP($F16,Taxa_från_edp!$B:$B,Taxa_från_edp!G:G),""),"") | J16: =IF($F16<>"",IFERROR(_xlfn.XLOOKUP($F16,Taxa_från_edp!$B:$B,Taxa_från_edp!K:K),""),"") | M16: =IFERROR(IF(J16<>"",J16*1.25,IF(K16<>"",K16*1.25,"")),"") | N16: =IFERROR(IF(J16<>"",L16*J16,IF(K16<>"",L16*K16,"")),"")
A17: §2.1 | B17: Grundavgift | C17: Administrativ avgift vid beviljad dispens om uppehåll i hämtning eller eget omhändertagande av avfall under kommunalt ansvar | E17: st/år | H17: =IF($F17<>"",IFERROR(_xlfn.XLOOKUP($F17,Taxa_från_edp!$B:$B,Taxa_från_edp!C:C),""),"") | I17: =IF($F17<>"",IFERROR(_xlfn.XLOOKUP($F17,Taxa_från_edp!$B:$B,Taxa_från_edp!G:G),""),"") | J17: =IF($F17<>"",IFERROR(_xlfn.XLOOKUP($F17,Taxa_från_edp!$B:$B,Taxa_från_edp!K:K),""),"") | M17: =IFERROR(IF(J17<>"",J17*1.25,IF(K17<>"",K17*1.25,"")),"") | N17: =IFERROR(IF(J17<>"",L17*J17,IF(K17<>"",L17*K17,"")),"")
A18: §2.2 Årlig hämtningsavgift per abonnemangstyp | G18: =IF($F18<>"",$F18,IFERROR(_xlfn.XLOOKUP(ROW(),Taxa_Saknas!$H:$H,Taxa_Saknas!$G:$G),"")) | H18: =IF($F18<>"",IFERROR(_xlfn.XLOOKUP($F18,Taxa_från_edp!$B:$B,Taxa_från_edp!C:C),""),"") | I18: =IF($F18<>"",IFERROR(_xlfn.XLOOKUP($F18,Taxa_från_edp!$B:$B,Taxa_från_edp!G:G),""),"") | J18: =IF($F18<>"",IFERROR(_xlfn.XLOOKUP($F18,Taxa_från_edp!$B:$B,Taxa_från_edp!K:K),""),"") | M18: =IFERROR(IF(J18<>"",J18*1.25,IF(K18<>"",K18*1.25,"")),"") | N18: =IFERROR(IF(J18<>"",L18*J18,IF(K18<>"",L18*K18,"")),"")
A19: §2.2.1 Hämtningsavgift per år för en- och tvåbostadshus | G19: =IF($F19<>"",$F19,IFERROR(_xlfn.XLOOKUP(ROW(),Taxa_Saknas!$H:$H,Taxa_Saknas!$G:$G),"")) | H19: =IF($F19<>"",IFERROR(_xlfn.XLOOKUP($F19,Taxa_från_edp!$B:$B,Taxa_från_edp!C:C),""),"") | I19: =IF($F19<>"",IFERROR(_xlfn.XLOOKUP($F19,Taxa_från_edp!$B:$B,Taxa_från_edp!G:G),""),"") | J19: =IF($F19<>"",IFERROR(_xlfn.XLOOKUP($F19,Taxa_från_edp!$B:$B,Taxa_från_edp!K:K),""),"") | M19: =IFERROR(IF(J19<>"",J19*1.25,IF(K19<>"",K19*1.25,"")),"") | N19: =IFERROR(IF(J19<>"",L19*J19,IF(K19<>"",L19*K19,"")),"")
A20: §2.2.1 | B20: Hämtningsavgift per år för en- och tvåbostadshus | C20: Kärl 240 l (mat-/restavfall) | D20: Hämtning var 14:e dag | E20: st/år | F20: KÄ240RM26 | G20: =IF($F20<>"",$F20,IFERROR(_xlfn.XLOOKUP(ROW(),Taxa_Saknas!$H:$H,Taxa_Saknas!$G:$G),"")) -> KÄ240RM26 | H20: =IF($F20<>"",IFERROR(_xlfn.XLOOKUP($F20,Taxa_från_edp!$B:$B,Taxa_från_edp!C:C),""),"") -> Tvåfackskärl , rest/matavfall. | I20: =IF($F20<>"",IFERROR(_xlfn.XLOOKUP($F20,Taxa_från_edp!$B:$B,Taxa_från_edp!G:G),""),"") -> ÅRKV | J20: =IF($F20<>"",IFERROR(_xlfn.XLOOKUP($F20,Taxa_från_edp!$B:$B,Taxa_från_edp!K:K),""),"") -> 640 | M20: =IFERROR(IF(J20<>"",J20*1.25,IF(K20<>"",K20*1.25,"")),"") -> 800 | N20: =IFERROR(IF(J20<>"",L20*J20,IF(K20<>"",L20*K20,"")),"") -> 0
A21: §2.2.1 | B21: Hämtningsavgift per år för en- och tvåbostadshus | C21: Kärl 240 l (mat-/restavfall) | D21: Hämtning månadsvis | E21: st/år | H21: =IF($F21<>"",IFERROR(_xlfn.XLOOKUP($F21,Taxa_från_edp!$B:$B,Taxa_från_edp!C:C),""),"") | I21: =IF($F21<>"",IFERROR(_xlfn.XLOOKUP($F21,Taxa_från_edp!$B:$B,Taxa_från_edp!G:G),""),"") | J21: =IF($F21<>"",IFERROR(_xlfn.XLOOKUP($F21,Taxa_från_edp!$B:$B,Taxa_från_edp!K:K),""),"") | M21: =IFERROR(IF(J21<>"",J21*1.25,IF(K21<>"",K21*1.25,"")),"") | N21: =IFERROR(IF(J21<>"",L21*J21,IF(K21<>"",L21*K21,"")),"")
A22: §2.2.1 | B22: Hämtningsavgift per år för en- och tvåbostadshus | C22: Extrakärl 190 l (restavfall) | D22: Hämtning var 14:e dag | E22: st/år | F22: KÄ190XRM26 | G22: =IF($F22<>"",$F22,IFERROR(_xlfn.XLOOKUP(ROW(),Taxa_Saknas!$H:$H,Taxa_Saknas!$G:$G),"")) -> KÄ190XRM26 | H22: =IF($F22<>"",IFERROR(_xlfn.XLOOKUP($F22,Taxa_från_edp!$B:$B,Taxa_från_edp!C:C),""),"") | I22: =IF($F22<>"",IFERROR(_xlfn.XLOOKUP($F22,Taxa_från_edp!$B:$B,Taxa_från_edp!G:G),""),"") | J22: =IF($F22<>"",IFERROR(_xlfn.XLOOKUP($F22,Taxa_från_edp!$B:$B,Taxa_från_edp!K:K),""),"") | M22: =IFERROR(IF(J22<>"",J22*1.25,IF(K22<>"",K22*1.25,"")),"") | N22: =IFERROR(IF(J22<>"",L22*J22,IF(K22<>"",L22*K22,"")),"")
A23: §2.2.1 | B23: Hämtningsavgift per år för en- och tvåbostadshus | C23: Extrakärl 190 l (restavfall) | D23: Hämtning månadsvis | E23: st/år | H23: =IF($F23<>"",IFERROR(_xlfn.XLOOKUP($F23,Taxa_från_edp!$B:$B,Taxa_från_edp!C:C),""),"") | I23: =IF($F23<>"",IFERROR(_xlfn.XLOOKUP($F23,Taxa_från_edp!$B:$B,Taxa_från_edp!G:G),""),"") | J23: =IF($F23<>"",IFERROR(_xlfn.XLOOKUP($F23,Taxa_från_edp!$B:$B,Taxa_från_edp!K:K),""),"") | M23: =IFERROR(IF(J23<>"",J23*1.25,IF(K23<>"",K23*1.25,"")),"") | N23: =IFERROR(IF(J23<>"",L23*J23,IF(K23<>"",L23*K23,"")),"")
A24: §2.2.1 | B24: Hämtningsavgift per år för en- och tvåbostadshus | C24: Kärl 370 l (papper-/plastförpackningar) | D24: Kostnadsfritt | E24: st/år | H24: =IF($F24<>"",IFERROR(_xlfn.XLOOKUP($F24,Taxa_från_edp!$B:$B,Taxa_från_edp!C:C),""),"") | I24: =IF($F24<>"",IFERROR(_xlfn.XLOOKUP($F24,Taxa_från_edp!$B:$B,Taxa_från_edp!G:G),""),"") | J24: =IF($F24<>"",IFERROR(_xlfn.XLOOKUP($F24,Taxa_från_edp!$B:$B,Taxa_från_edp!K:K),""),"") | M24: =IFERROR(IF(J24<>"",J24*1.25,IF(K24<>"",K24*1.25,"")),"") | N24: =IFERROR(IF(J24<>"",L24*J24,IF(K24<>"",L24*K24,"")),"")
A25: §2.2.2 Hämtningsavgift per år för fritidshus inom hämtningsområde X | G25: =IF($F25<>"",$F25,IFERROR(_xlfn.XLOOKUP(ROW(),Taxa_Saknas!$H:$H,Taxa_Saknas!$G:$G),"")) | H25: =IF($F25<>"",IFERROR(_xlfn.XLOOKUP($F25,Taxa_från_edp!$B:$B,Taxa_från_edp!C:C),""),"") | I25: =IF($F25<>"",IFERROR(_xlfn.XLOOKUP($F25,Taxa_från_edp!$B:$B,Taxa_från_edp!G:G),""),"") | J25: =IF($F25<>"",IFERROR(_xlfn.XLOOKUP($F25,Taxa_från_edp!$B:$B,Taxa_från_edp!K:K),""),"") | M25: =IFERROR(IF(J25<>"",J25*1.25,IF(K25<>"",K25*1.25,"")),"") | N25: =IFERROR(IF(J25<>"",L25*J25,IF(K25<>"",L25*K25,"")),"")
A26: §2.2.2 | B26: Hämtningsavgift per år för fritidshus | C26: Kärl 240 l (mat-/restavfall) | D26: Hämtning var 14:e dag | E26: st/år | F26: KÄ240RM26 | G26: =IF($F26<>"",$F26,IFERROR(_xlfn.XLOOKUP(ROW(),Taxa_Saknas!$H:$H,Taxa_Saknas!$G:$G),"")) -> KÄ240RM26 | H26: =IF($F26<>"",IFERROR(_xlfn.XLOOKUP($F26,Taxa_från_edp!$B:$B,Taxa_från_edp!C:C),""),"") -> Tvåfackskärl , rest/matavfall. | I26: =IF($F26<>"",IFERROR(_xlfn.XLOOKUP($F26,Taxa_från_edp!$B:$B,Taxa_från_edp!G:G),""),"") -> ÅRKV | J26: =IF($F26<>"",IFERROR(_xlfn.XLOOKUP($F26,Taxa_från_edp!$B:$B,Taxa_från_edp!K:K),""),"") -> 640 | M26: =IFERROR(IF(J26<>"",J26*1.25,IF(K26<>"",K26*1.25,"")),"") -> 800 | N26: =IFERROR(IF(J26<>"",L26*J26,IF(K26<>"",L26*K26,"")),"") -> 0
A27: §2.2.2 | B27: Hämtningsavgift per år för fritidshus | C27: Kärl 240 l (mat-/restavfall) | D27: Hämtning månadsvis | E27: st/år | H27: =IF($F27<>"",IFERROR(_xlfn.XLOOKUP($F27,Taxa_från_edp!$B:$B,Taxa_från_edp!C:C),""),"") | I27: =IF($F27<>"",IFERROR(_xlfn.XLOOKUP($F27,Taxa_från_edp!$B:$B,Taxa_från_edp!G:G),""),"") | J27: =IF($F27<>"",IFERROR(_xlfn.XLOOKUP($F27,Taxa_från_edp!$B:$B,Taxa_från_edp!K:K),""),"") | M27: =IFERROR(IF(J27<>"",J27*1.25,IF(K27<>"",K27*1.25,"")),"") | N27: =IFERROR(IF(J27<>"",L27*J27,IF(K27<>"",L27*K27,"")),"")
A28: §2.2.2 | B28: Hämtningsavgift per år för fritidshus | C28: Extrakärl 190 l (restavfall) | D28: Hämtning var 14:e dag | E28: st/år | F28: KÄ190XRM26FRI | G28: =IF($F28<>"",$F28,IFERROR(_xlfn.XLOOKUP(ROW(),Taxa_Saknas!$H:$H,Taxa_Saknas!$G:$G),"")) -> KÄ190XRM26FRI | H28: =IF($F28<>"",IFERROR(_xlfn.XLOOKUP($F28,Taxa_från_edp!$B:$B,Taxa_från_edp!C:C),""),"") | I28: =IF($F28<>"",IFERROR(_xlfn.XLOOKUP($F28,Taxa_från_edp!$B:$B,Taxa_från_edp!G:G),""),"") | J28: =IF($F28<>"",IFERROR(_xlfn.XLOOKUP($F28,Taxa_från_edp!$B:$B,Taxa_från_edp!K:K),""),"") | M28: =IFERROR(IF(J28<>"",J28*1.25,IF(K28<>"",K28*1.25,"")),"") | N28: =IFERROR(IF(J28<>"",L28*J28,IF(K28<>"",L28*K28,"")),"")
A29: §2.2.2 | B29: Hämtningsavgift per år för fritidshus | C29: Kärl 370 l (papper-/plastförpackningar) | D29: Kostnadsfritt | E29: st/år | H29: =IF($F29<>"",IFERROR(_xlfn.XLOOKUP($F29,Taxa_från_edp!$B:$B,Taxa_från_edp!C:C),""),"") | I29: =IF($F29<>"",IFERROR(_xlfn.XLOOKUP($F29,Taxa_från_edp!$B:$B,Taxa_från_edp!G:G),""),"") | J29: =IF($F29<>"",IFERROR(_xlfn.XLOOKUP($F29,Taxa_från_edp!$B:$B,Taxa_från_edp!K:K),""),"") | M29: =IFERROR(IF(J29<>"",J29*1.25,IF(K29<>"",K29*1.25,"")),"") | N29: =IFERROR(IF(J29<>"",L29*J29,IF(K29<>"",L29*K29,"")),"")
A30: §2.2.3 Gemensam uppsamlingsplats inom hämtningsområde X | G30: =IF($F30<>"",$F30,IFERROR(_xlfn.XLOOKUP(ROW(),Taxa_Saknas!$H:$H,Taxa_Saknas!$G:$G),"")) | H30: =IF($F30<>"",IFERROR(_xlfn.XLOOKUP($F30,Taxa_från_edp!$B:$B,Taxa_från_edp!C:C),""),"") | I30: =IF($F30<>"",IFERROR(_xlfn.XLOOKUP($F30,Taxa_från_edp!$B:$B,Taxa_från_edp!G:G),""),"") | J30: =IF($F30<>"",IFERROR(_xlfn.XLOOKUP($F30,Taxa_från_edp!$B:$B,Taxa_från_edp!K:K),""),"") | M30: =IFERROR(IF(J30<>"",J30*1.25,IF(K30<>"",K30*1.25,"")),"") | N30: =IFERROR(IF(J30<>"",L30*J30,IF(K30<>"",L30*K30,"")),"")
A31: §2.2.3 | B31: Gemensam uppsamlingsplats inom hämtningsområde X | C31: Gemensam uppsamlingsplats för mat-/restavfall | E31: st/år | F31: GEMUPPFRI | G31: =IF($F31<>"",$F31,IFERROR(_xlfn.XLOOKUP(ROW(),Taxa_Saknas!$H:$H,Taxa_Saknas!$G:$G),"")) -> GEMUPPFRI | H31: =IF($F31<>"",IFERROR(_xlfn.XLOOKUP($F31,Taxa_från_edp!$B:$B,Taxa_från_edp!C:C),""),"") | I31: =IF($F31<>"",IFERROR(_xlfn.XLOOKUP($F31,Taxa_från_edp!$B:$B,Taxa_från_edp!G:G),""),"") | J31: =IF($F31<>"",IFERROR(_xlfn.XLOOKUP($F31,Taxa_från_edp!$B:$B,Taxa_från_edp!K:K),""),"") | M31: =IFERROR(IF(J31<>"",J31*1.25,IF(K31<>"",K31*1.25,"")),"") | N31: =IFERROR(IF(J31<>"",L31*J31,IF(K31<>"",L31*K31,"")),"")
A32: §2.2.3 | B32: Gemensam uppsamlingsplats inom hämtningsområde X | C32: Gemensam uppsamlingsplats för förpackningar | D32: Kostnadsfritt | E32: st/år | H32: =IF($F32<>"",IFERROR(_xlfn.XLOOKUP($F32,Taxa_från_edp!$B:$B,Taxa_från_edp!C:C),""),"") | I32: =IF($F32<>"",IFERROR(_xlfn.XLOOKUP($F32,Taxa_från_edp!$B:$B,Taxa_från_edp!G:G),""),"") | J32: =IF($F32<>"",IFERROR(_xlfn.XLOOKUP($F32,Taxa_från_edp!$B:$B,Taxa_från_edp!K:K),""),"") | M32: =IFERROR(IF(J32<>"",J32*1.25,IF(K32<>"",K32*1.25,"")),"") | N32: =IFERROR(IF(J32<>"",L32*J32,IF(K32<>"",L32*K32,"")),"")
A33: §2.2.3 | B33: Gemensam uppsamlingsplats inom hämtningsområde X | C33: Extra digital licens (årskostnad) | E33: st/år | H33: =IF($F33<>"",IFERROR(_xlfn.XLOOKUP($F33,Taxa_från_edp!$B:$B,Taxa_från_edp!C:C),""),"") | I33: =IF($F33<>"",IFERROR(_xlfn.XLOOKUP($F33,Taxa_från_edp!$B:$B,Taxa_från_edp!G:G),""),"") | J33: =IF($F33<>"",IFERROR(_xlfn.XLOOKUP($F33,Taxa_från_edp!$B:$B,Taxa_från_edp!K:K),""),"") | M33: =IFERROR(IF(J33<>"",J33*1.25,IF(K33<>"",K33*1.25,"")),"") | N33: =IFERROR(IF(J33<>"",L33*J33,IF(K33<>"",L33*K33,"")),"")
A34: §2.2.3 | B34: Gemensam uppsamlingsplats inom hämtningsområde X | C34: Fysisk nyckel, kallad fob (engångskostnad) | E34: st/tillfälle | H34: =IF($F34<>"",IFERROR(_xlfn.XLOOKUP($F34,Taxa_från_edp!$B:$B,Taxa_från_edp!C:C),""),"") | I34: =IF($F34<>"",IFERROR(_xlfn.XLOOKUP($F34,Taxa_från_edp!$B:$B,Taxa_från_edp!G:G),""),"") | J34: =IF($F34<>"",IFERROR(_xlfn.XLOOKUP($F34,Taxa_från_edp!$B:$B,Taxa_från_edp!K:K),""),"") | M34: =IFERROR(IF(J34<>"",J34*1.25,IF(K34<>"",K34*1.25,"")),"") | N34: =IFERROR(IF(J34<>"",L34*J34,IF(K34<>"",L34*K34,"")),"")
A35: §2.2.3 | B35: Gemensam uppsamlingsplats inom hämtningsområde X | C35: Byte av telefonnummer kopplat till licens | E35: st/tillfälle | H35: =IF($F35<>"",IFERROR(_xlfn.XLOOKUP($F35,Taxa_från_edp!$B:$B,Taxa_från_edp!C:C),""),"") | I35: =IF($F35<>"",IFERROR(_xlfn.XLOOKUP($F35,Taxa_från_edp!$B:$B,Taxa_från_edp!G:G),""),"") | J35: =IF($F35<>"",IFERROR(_xlfn.XLOOKUP($F35,Taxa_från_edp!$B:$B,Taxa_från_edp!K:K),""),"") | M35: =IFERROR(IF(J35<>"",J35*1.25,IF(K35<>"",K35*1.25,"")),"") | N35: =IFERROR(IF(J35<>"",L35*J35,IF(K35<>"",L35*K35,"")),"")
A36: §2.2.3 | B36: Gemensam uppsamlingsplats inom hämtningsområde X | C36: Kostnad för öppning av behållare | E36: st/tillfälle | H36: =IF($F36<>"",IFERROR(_xlfn.XLOOKUP($F36,Taxa_från_edp!$B:$B,Taxa_från_edp!C:C),""),"") | I36: =IF($F36<>"",IFERROR(_xlfn.XLOOKUP($F36,Taxa_från_edp!$B:$B,Taxa_från_edp!G:G),""),"") | J36: =IF($F36<>"",IFERROR(_xlfn.XLOOKUP($F36,Taxa_från_edp!$B:$B,Taxa_från_edp!K:K),""),"") | M36: =IFERROR(IF(J36<>"",J36*1.25,IF(K36<>"",K36*1.25,"")),"") | N36: =IFERROR(IF(J36<>"",L36*J36,IF(K36<>"",L36*K36,"")),"")
A37: §2.2.4 Hämtningsavgift per år för flerbostadshus inom hämtningsområde X | G37: =IF($F37<>"",$F37,IFERROR(_xlfn.XLOOKUP(ROW(),Taxa_Saknas!$H:$H,Taxa_Saknas!$G:$G),"")) | H37: =IF($F37<>"",IFERROR(_xlfn.XLOOKUP($F37,Taxa_från_edp!$B:$B,Taxa_från_edp!C:C),""),"") | I37: =IF($F37<>"",IFERROR(_xlfn.XLOOKUP($F37,Taxa_från_edp!$B:$B,Taxa_från_edp!G:G),""),"") | J37: =IF($F37<>"",IFERROR(_xlfn.XLOOKUP($F37,Taxa_från_edp!$B:$B,Taxa_från_edp!K:K),""),"") | M37: =IFERROR(IF(J37<>"",J37*1.25,IF(K37<>"",K37*1.25,"")),"") | N37: =IFERROR(IF(J37<>"",L37*J37,IF(K37<>"",L37*K37,"")),"")
A38: §2.2.4 | B38: Hämtningsavgift per år för flerbostadshus | C38: Kärl 240 l (mat-/restavfall) | D38: Hämtning varje vecka | E38: st/år | H38: =IF($F38<>"",IFERROR(_xlfn.XLOOKUP($F38,Taxa_från_edp!$B:$B,Taxa_från_edp!C:C),""),"") | I38: =IF($F38<>"",IFERROR(_xlfn.XLOOKUP($F38,Taxa_från_edp!$B:$B,Taxa_från_edp!G:G),""),"") | J38: =IF($F38<>"",IFERROR(_xlfn.XLOOKUP($F38,Taxa_från_edp!$B:$B,Taxa_från_edp!K:K),""),"") | M38: =IFERROR(IF(J38<>"",J38*1.25,IF(K38<>"",K38*1.25,"")),"") | N38: =IFERROR(IF(J38<>"",L38*J38,IF(K38<>"",L38*K38,"")),"")
A39: §2.2.4 | B39: Hämtningsavgift per år för flerbostadshus | C39: Kärl 240 l (mat-/restavfall) | D39: Hämtning var 14:e dag | E39: st/år | F39: KÄ240RM26FV | G39: =IF($F39<>"",$F39,IFERROR(_xlfn.XLOOKUP(ROW(),Taxa_Saknas!$H:$H,Taxa_Saknas!$G:$G),"")) -> KÄ240RM26FV | H39: =IF($F39<>"",IFERROR(_xlfn.XLOOKUP($F39,Taxa_från_edp!$B:$B,Taxa_från_edp!C:C),""),"") -> Tvåfackskärl, rest/mat FLB/VHT | I39: =IF($F39<>"",IFERROR(_xlfn.XLOOKUP($F39,Taxa_från_edp!$B:$B,Taxa_från_edp!G:G),""),"") -> ÅRKV | J39: =IF($F39<>"",IFERROR(_xlfn.XLOOKUP($F39,Taxa_från_edp!$B:$B,Taxa_från_edp!K:K),""),"") -> 640 | M39: =IFERROR(IF(J39<>"",J39*1.25,IF(K39<>"",K39*1.25,"")),"") -> 800 | N39: =IFERROR(IF(J39<>"",L39*J39,IF(K39<>"",L39*K39,"")),"") -> 0
A40: §2.2.4 | B40: Hämtningsavgift per år för flerbostadshus | C40: Kärl 240 l (mat-/restavfall) | D40: Hämtning månadsvis | E40: st/år | H40: =IF($F40<>"",IFERROR(_xlfn.XLOOKUP($F40,Taxa_från_edp!$B:$B,Taxa_från_edp!C:C),""),"") | I40: =IF($F40<>"",IFERROR(_xlfn.XLOOKUP($F40,Taxa_från_edp!$B:$B,Taxa_från_edp!G:G),""),"") | J40: =IF($F40<>"",IFERROR(_xlfn.XLOOKUP($F40,Taxa_från_edp!$B:$B,Taxa_från_edp!K:K),""),"") | M40: =IFERROR(IF(J40<>"",J40*1.25,IF(K40<>"",K40*1.25,"")),"") | N40: =IFERROR(IF(J40<>"",L40*J40,IF(K40<>"",L40*K40,"")),"")
A41: §2.2.4 | B41: Hämtningsavgift per år för flerbostadshus | C41: Kärl 370 l (restavfall) | D41: Hämtning varje vecka | E41: st/år | H41: =IF($F41<>"",IFERROR(_xlfn.XLOOKUP($F41,Taxa_från_edp!$B:$B,Taxa_från_edp!C:C),""),"") | I41: =IF($F41<>"",IFERROR(_xlfn.XLOOKUP($F41,Taxa_från_edp!$B:$B,Taxa_från_edp!G:G),""),"") | J41: =IF($F41<>"",IFERROR(_xlfn.XLOOKUP($F41,Taxa_från_edp!$B:$B,Taxa_från_edp!K:K),""),"") | M41: =IFERROR(IF(J41<>"",J41*1.25,IF(K41<>"",K41*1.25,"")),"") | N41: =IFERROR(IF(J41<>"",L41*J41,IF(K41<>"",L41*K41,"")),"")
A42: §2.2.4 | B42: Hämtningsavgift per år för flerbostadshus | C42: Kärl 370 l (restavfall) | D42: Hämtning var 14:e dag | E42: st/år | F42: KÄ370RE26FV | G42: =IF($F42<>"",$F42,IFERROR(_xlfn.XLOOKUP(ROW(),Taxa_Saknas!$H:$H,Taxa_Saknas!$G:$G),"")) -> KÄ370RE26FV | H42: =IF($F42<>"",IFERROR(_xlfn.XLOOKUP($F42,Taxa_från_edp!$B:$B,Taxa_från_edp!C:C),""),"") -> Kärl 370 L, rest. FLB/VHT | I42: =IF($F42<>"",IFERROR(_xlfn.XLOOKUP($F42,Taxa_från_edp!$B:$B,Taxa_från_edp!G:G),""),"") -> ÅRKV | J42: =IF($F42<>"",IFERROR(_xlfn.XLOOKUP($F42,Taxa_från_edp!$B:$B,Taxa_från_edp!K:K),""),"") -> 800 | M42: =IFERROR(IF(J42<>"",J42*1.25,IF(K42<>"",K42*1.25,"")),"") -> 1000 | N42: =IFERROR(IF(J42<>"",L42*J42,IF(K42<>"",L42*K42,"")),"") -> 0
...

Sheet Taxepunkter_Rådata
A1: Paragraf | B1: Paragrafnamn | C1: Taxapunkt | D1: Variant | E1: Enhet | F1: Taxakod | G1: Taxabeskrivning | H1: Faktor | I1: Aktuellt pris (exkl m) | J1: Antal | K1: Pris (kr) | L1: Intäkt (kr)
A2: =Taxepunkter!A9 -> §2.1 | B2: =Taxepunkter!B9 -> Grundavgift | C2: =Taxepunkter!C9 -> En- och tvåbostadshus | D2: =Taxepunkter!D9 -> 0 | E2: =Taxepunkter!E9 -> st/år | F2: =Taxepunkter!F9 -> GRUNDPER | G2: =Taxepunkter!G9 -> GRUNDPER | H2: =Taxepunkter!H9 -> Grundavgift permanentboende | ... L2: =Taxepunkter!L9 -> 0
A3: =Taxepunkter!A10 -> §2.1 | B3: =Taxepunkter!B10 -> Grundavgift | C3: =Taxepunkter!C10 -> Fritidshus | D3: =Taxepunkter!D10 -> 0 | E3: =Taxepunkter!E10 -> st/år | F3: =Taxepunkter!F10 -> GRUNDFRI | G3: =Taxepunkter!G10 -> GRUNDFRI | H3: =Taxepunkter!H10 -> Grundavgift fritidshus | ... L3: =Taxepunkter!L10 -> 0
A4: =Taxepunkter!A11 -> §2.1 | B4: =Taxepunkter!B11 -> Grundavgift | C4: =Taxepunkter!C11 -> Verksamhet | D4: =Taxepunkter!D11 -> 0 | E4: =Taxepunkter!E11 -> st/år | F4: =Taxepunkter!F11 -> GRUNDLÄG | G4: =Taxepunkter!G11 -> GRUNDLÄG | H4: =Taxepunkter!H11 -> Grundavgift, tvåbostadshus | ... L4: =Taxepunkter!L11 -> 0
A5: =Taxepunkter!A12 -> §2.1 | B5: =Taxepunkter!B12 -> Grundavgift | C5: =Taxepunkter!C12 -> Lägenhet i flerbostadshus | D5: =Taxepunkter!D12 -> 0 | E5: =Taxepunkter!E12 -> st/år | F5: =Taxepunkter!F12 -> GRUNDFLB | G5: =Taxepunkter!G12 -> GRUNDFLB | H5: =Taxepunkter!H12 -> Grundavgift per lägenhet, flerbostadshus | ... L5: =Taxepunkter!L12 -> 0
A6: =Taxepunkter!A13 -> §2.1 | B6: =Taxepunkter!B13 -> Grundavgift | C6: =Taxepunkter!C13 -> Lägenhet för specialändamål | D6: =Taxepunkter!D13 -> 0 | E6: =Taxepunkter!E13 -> st/år | F6: =Taxepunkter!F13 -> 0 | G6: =Taxepunkter!G13 -> 0 | H6: =Taxepunkter!H13 | ... L6: =Taxepunkter!L13 -> 0
A7: =Taxepunkter!A14 -> §2.1 | B7: =Taxepunkter!B14 -> Grundavgift | C7: =Taxepunkter!C14 -> Anläggning | D7: =Taxepunkter!D14 -> 0 | E7: =Taxepunkter!E14 -> st/år | F7: =Taxepunkter!F14 -> 0 | G7: =Taxepunkter!G14 -> 0 | H7: =Taxepunkter!H14 | ... L7: =Taxepunkter!L14 -> 0
A8: =Taxepunkter!A15 -> §2.1 | B8: =Taxepunkter!B15 -> Grundavgift | C8: =Taxepunkter!C15 -> Säsongsbaserad uppställningsplats | D8: =Taxepunkter!D15 -> 0 | E8: =Taxepunkter!E15 -> st/år | F8: =Taxepunkter!F15 -> 0 | G8: =Taxepunkter!G15 -> 0 | H8: =Taxepunkter!H15 | ... L8: =Taxepunkter!L15 -> 0
A9: =Taxepunkter!A16 -> §2.1 | B9: =Taxepunkter!B16 -> Grundavgift | C9: =Taxepunkter!C16 -> Campingstuga/-lägenhet | D9: =Taxepunkter!D16 -> 0 | E9: =Taxepunkter!E16 -> st/år | F9: =Taxepunkter!F16 -> 0 | G9: =Taxepunkter!G16 -> 0 | H9: =Taxepunkter!H16 | ... L9: =Taxepunkter!L16 -> 0
A10: =Taxepunkter!A17 -> §2.1 | B10: =Taxepunkter!B17 -> Grundavgift | C10: =Taxepunkter!C17 -> Administrativ avgift vid beviljad dispens om uppehåll i hämtning eller eget omhändertagande av avfall under kommunalt ansvar | D10: =Taxepunkter!D17 -> 0 | E10: =Taxepunkter!E17 -> st/år | F10: =Taxepunkter!F17 -> 0 | G10: =Taxepunkter!G17 -> 0 | H10: =Taxepunkter!H17 | ... L10: =Taxepunkter!L17 -> 0
A11: =Taxepunkter!A18 -> §2.2 Årlig hämtningsavgift per abonnemangstyp | B11: =Taxepunkter!B18 -> 0 | C11: =Taxepunkter!C18 -> 0 | D11: =Taxepunkter!D18 -> 0 | E11: =Taxepunkter!E18 -> 0 | F11: =Taxepunkter!F18 -> 0 | G11: =Taxepunkter!G18 | H11: =Taxepunkter!H18 | ... L11: =Taxepunkter!L18 -> 0
A12: =Taxepunkter!A19 -> §2.2.1 Hämtningsavgift per år för en- och tvåbostadshus | B12: =Taxepunkter!B19 -> 0 | C12: =Taxepunkter!C19 -> 0 | D12: =Taxepunkter!D19 -> 0 | E12: =Taxepunkter!E19 -> 0 | F12: =Taxepunkter!F19 -> 0 | G12: =Taxepunkter!G19 | H12: =Taxepunkter!H19 | ... L12: =Taxepunkter!L19 -> 0
A13: =Taxepunkter!A20 -> §2.2.1 | B13: =Taxepunkter!B20 -> Hämtningsavgift per år för en- och tvåbostadshus | C13: =Taxepunkter!C20 -> Kärl 240 l (mat-/restavfall) | D13: =Taxepunkter!D20 -> Hämtning var 14:e dag | E13: =Taxepunkter!E20 -> st/år | F13: =Taxepunkter!F20 -> KÄ240RM26 | G13: =Taxepunkter!G20 -> KÄ240RM26 | H13: =Taxepunkter!H20 -> Tvåfackskärl , rest/matavfall. | ... L13: =Taxepunkter!L20 -> 0
... A361: =Taxepunkter!A368 -> §6.1.6 | B361: =Taxepunkter!B368 -> Tillägg och avgifter | C361: =Taxepunkter!C368 -> ombud för registrering av El-kretsen avlämnarintyg i Hämtplatsportalen | D361: =Taxepunkter!D368 -> 0 | E361: =Taxepunkter!E368 -> st/år | F361: =Taxepunkter!F368 -> 0 | G361: =Taxepunkter!G368 | H361: =Taxepunkter!H368 | ... L361: =Taxepunkter!L368 -> 0

Sheet Taxa_från_edp
A1: intRecnum | B1: strTaxekod | C1: strTaxebenamning | D1: strProdukt | E1: strDelProdukt | F1: bytDelradnr | G1: strFaktor | H1: strTaxedelAvser | I1: strEntreprenorkod | J1: strRenhDistrKod | K1: curNuvarandePris | L1: datNuvarandePrisDatum | M1: bolPrisPerTomning | N1: strAvvikandeFormel | O1: bolPriserInklMoms | P1: bytMomskod | Q1: strFormel
A2: 13 | B2: A | C2: AVLOPP BOSTADSHUS | D2: VA | E2: AVL | F2: 1 | G2: ÅRPR | H2: Avlopp bostadshus | K2: 2762 | L2: 45658 | M2: 0 | O2: - | P2: 1
A3: 14 | B3: AF | C3: AVLOPP FRITIDSHUS | D3: VA | E3: AVL | F3: 1 | G3: ÅRPR | H3: Avlopp fritidshus | K3: 1939 | L3: 45658 | M3: 0 | O3: - | P3: 1
A4: 15 | B4: AFC | C4: AVLOPP FRITIDSHUS CAMPING | D4: VA | E4: AVL | F4: 1 | G4: ÅRKV | H4: Avlopp fritidshus | K4: 1112 | L4: 39814 | M4: 0 | O4: - | P4: 1 | Q4: KETT
A5: 16 | B5: AKUT | C5: EXTRAAVGIFT AKUT SLAMTÖMNING | D5: RENH | E5: SLAM | F5: 1 | G5: KVAN | H5: Extraavg akut slamtömning | K5: 640 | L5: 43922 | M5: 0 | O5: - | P5: 1 | Q5: ANTL
A6: 178 | B6: AKUTSÄCK | C6: Avgift för akutsäck | D6: RENH | E6: HUSH | F6: 1 | G6: KVAN | H6: Avgift för akutsäck | K6: 160 | L6: 45200 | M6: 0 | O6: - | P6: 1 | Q6: ANTL
A7: 2 | B7: AMOAVISER | C7: Amorteringsplanavisering | D7: VA | F7: 1 | G7: KVAN | H7: Amorteringsplanavisering | K7: 20 | L7: 32874 | M7: 0 | O7: - | P7: 0
A8: 12 | B8: AMOPLAN | C8: Amorteringsplan | D8: VA | F8: 1 | G8: KVAN | H8: Amorteringsplan | M8: 0 | O8: - | P8: 0 | Q8: ANTL
A9: 3 | B9: AMORÄNTA | C9: Amorteringsplanränta | D9: VA | F9: 1 | G9: KVAN | H9: Amorteringsplanränta | K9: 0 | L9: 32874 | M9: 0 | O9: - | P9: 0
A10: 1 | B10: AMOUPP | C10: Amorteringsplansuppläggning | D10: VA | F10: 1 | G10: KVAN | H10: Amorteringsplansuppläggning | K10: 150 | L10: 32874 | M10: 0 | O10: - | P10: 0
A11: 127 | B11: ANL03SL | C11: Tömning slamanläggning | D11: RENH | E11: SLAM | F11: 1 | G11: KVAN | H11: Tömning av slamanläggning | K11: 1420 | L11: 45658 | M11: 0 | O11: - | P11: 1 | Q11: ANTL
A12: 128 | B12: ANL36SL | C12: Tömning slamanläggning 3,1-6 m³ | D12: RENH | E12: SLAM | F12: 1 | G12: KVAN | H12: Tömning av slamanlägg. 3,1-6 | K12: 1920 | L12: 45658 | M12: 0 | O12: - | P12: 1 | Q12: ANTL
A13: 294 | B13: ANLSLBASTÖM | C13: Tömning slam från Reningsverksbassäng | D13: RENH | E13: SLAM | F13: 1 | G13: KVAN | H13: Tömning slam från Reningsverksbassäng | K13: 0 | L13: 45658 | M13: 0 | O13: - | P13: 1 | Q13: ANTL
A14: 129 | B14: ANLÖ6SL | C14: Tömning slamanläggning över 6 m³ | D14: RENH | E14: SLAM | F14: 1 | G14: KVAN | H14: Tömning av slamanlägg över 6 m³ | K14: 2448 | L14: 45658 | M14: 0 | O14: - | P14: 1 | Q14: ANTL
A15: 156 | B15: AOBF | C15: A, OBEBYGGD FAST. INOM DETALJPLAN | D15: VA | E15: AVL | F15: 1 | G15: ÅRPR | H15: Avlopp obebygg inom detaljp | K15: 2200 | L15: 45078 | M15: 0 | O15: - | P15: 1
A16: 287 | B16: AVSLUTA_TJÄNST | C16: Dummy för avslut av tjänst via order | D16: RENH | E16: HUSH | F16: 1 | G16: KVAN | H16: Avslut av tjänst | M16: 0 | O16: - | P16: 0 | Q16: 0
A17: 293 | B17: BASSLORDKOM | C17: Reningsverksbassäng, slam. Ord. tur Kommunal | D17: RENH | E17: SLAM | F17: 1 | G17: ÅRKV | H17: Reningsverksbassäng, slam. Ord. tur Kommunal | K17: 0 | L17: 44927 | M17: 0 | O17: - | P17: 1 | Q17: ANTB
A18: 115 | B18: BDT03SLBUD | C18: BDT 0-3 m³, slam. Budning | D18: RENH | E18: SLAM | F18: 1 | G18: ÅRKV | H18: BDT 0-3 m³, slam. Budning | K18: 800 | L18: 45658 | M18: 0 | O18: - | P18: 1 | Q18: ANTB
A19: 142 | B19: BDT03SLORD | C19: BDT 0-3 m³, slam. Ordinarie tur | D19: RENH | E19: SLAM | F19: 1 | G19: ÅRKV | H19: BDT 0-3 m³, slam. Ord. tur | K19: 1420 | L19: 45658 | M19: 0 | O19: - | P19: 1 | Q19: ANTB
A20: 116 | B20: BDT36SLBUD | C20: BDT 3,1-6 m³, slam. Budning | D20: RENH | E20: SLAM | F20: 1 | G20: ÅRKV | H20: BDT 3,1-6 m³, slam. Budning | K20: 0 | L20: 44927 | M20: 0 | O20: - | P20: 1 | Q20: ANTB
A21: 143 | B21: BDT36SLORD | C21: BDT 3,1-6 m³, slam. Ord. tur | D21: RENH | E21: SLAM | F21: 1 | G21: ÅRKV | H21: BDT 3,1-6 m³, slam. Ord. tur | K21: 0 | L21: 44927 | M21: 0 | O21: - | P21: 1 | Q21: ANTB
A22: 117 | B22: BDTÖ6SLBUD | C22: BDT över 6 m³, slam. Budning | D22: RENH | E22: SLAM | F22: 1 | G22: ÅRKV | H22: BDT över 6 m³, slam. Budning | K22: 0 | L22: 44927 | M22: 0 | O22: - | P22: 1 | Q22: ANTB
A23: 144 | B23: BDTÖ6SLORD | C23: BDT över 6 m³, slam. Ord. tur | D23: RENH | E23: SLAM | F23: 1 | G23: ÅRKV | H23: BDT över 6 m³, slam. Ord. tur | K23: 0 | L23: 44927 | M23: 0 | O23: - | P23: 1 | Q23: ANTB
A24: 262 | B24: BEHASKA | C24: Behandlingsavgift Aska | D24: RENH | E24: CONT | F24: 1 | G24: KVAN | H24: Behandlingsavgift Aska | K24: 650 | L24: 45658 | M24: 0 | O24: - | P24: 1 | Q24: KBM
A25: 267 | B25: BEHREST | C25: Behandlingsavgift Restavfall | D25: RENH | E25: CONT | F25: 1 | G25: KVAN | H25: Behandlingsavgift Restavfall | K25: 2500 | L25: 45658 | M25: 0 | O25: - | P25: 1 | Q25: VITO
A26: 289 | B26: BEHSLAM | C26: Behandlingsavgift Slam | D26: RENH | E26: CONT | F26: 1 | G26: KVAN | H26: Behandlingsavgift Slam | K26: 0 | L26: 45658 | M26: 0 | O26: - | P26: 1 | Q26: KBM
A27: 296 | B27: BEHSLAMSTAT | C27: Behandlingsavgift Slam Statistik | D27: RENH | E27: CONT | F27: 1 | G27: KVAN | H27: Behandlingsavgift Slam | K27: 0 | L27: 45658 | M27: 0 | O27: - | P27: 1 | Q27: KBM
A28: 162 | B28: BETALSÄCK | C28: Betalsäck, pris per säck | D28: RENH | E28: HUSH | F28: 1 | G28: KVAN | H28: Betalsäck, pris per säck | K28: 128 | L28: 45200 | M28: 0 | O28: - | P28: 1 | Q28: ANTL
... A42: 18 | B42: DE190 | C42: 190 L KÄRL DELAT | D42: RENH | E42: HUSH | F42: 1 | G42: ÅRKV | H42: Sophämtning delat 190 l kärl | K42: 706 | L42: 40179 | M42: 0 | O42: - | P42: 1 | Q42: ANTB
A43: 7 | B43: DRÖJRÄNTA | C43: Dröjsmålsränta | D43: VA | F43: 1 | G43: KVAN | H43: Dröjsmålsränta | K43: 0 | L43: 32874 | M43: 0 | O43: - | P43: 0
A44: 184 | B44: EVEKÄ140MA | C44: Evenemangskärl 140 L, matavfall | D44: RENH | E44: HUSH | F44: 1 | G44: KVAN | H44: Evenemangskärl 140 L, matavfall | K44: 1000 | L44: 45200 | M44: 0 | O44: - | P44: 1 | Q44: ANTL
A45: 185 | B45: EVEKÄ190RE | C45: Evenemangskärl 190 L, restavfall | D45: RENH | E45: HUSH | F45: 1 | G45: KVAN | H45: Evenemangskärl 190 L, restavfall | K45: 1200 | L45: 45200 | M45: 0 | O45: - | P45: 1 | Q45: ANTL
A46: 186 | B46: EVEKÄ660RE | C46: Evenemangskärl 660 L, restavfall | D46: RENH | E46: HUSH | F46: 1 | G46: KVAN | H46: Evenemangskärl 660 L, restavfall | K46: 2000 | L46: 45200 | M46: 0 | O46: - | P46: 1 | Q46: ANTL
A47: 187 | B47: EVENEMANG | C47: Tjänsttaxa för tillfälliga evenemangskärl | D47: RENH | E47: HUSH | F47: 1 | G47: ÅRKV | H47: Tjänsttaxa för evenemangskärl | K47: 0 | L47: 45200 | M47: 0 | O47: - | P47: 1 | Q47: 0
A48: 19 | B48: EXTRA | C48: Efteranmälan slamtömning | D48: RENH | E48: SLAM | F48: 1 | G48: KVAN | H48: Förseningsavgift efteranmälan | K48: 640 | L48: 43922 | M48: 0 | O48: - | P48: 1 | Q48: ANTL
A49: 166 | B49: FARLIGTBUD | C49: Budning av farligt avfall, pris per tillfälle | D49: RENH | E49: HUSH | F49: 1 | G49: KVAN | H49: Budning av farligt avfall, pris per tillfälle | K49: 1600 | L49: 45200 | M49: 0 | O49: - | P49: 1 | Q49: ANTL
A50: 163 | B50: FELSORT | C50: Felsorteringsavgift, pris per tillfälle och kärl | D50: RENH | E50: HUSH | F50: 1 | G50: KVAN | H50: Felsorteringsavgift, pris per tillfälle och kärl | K50: 400 | L50: 45200 | M50: 0 | O50: - | P50: 1 | Q50: ANTL
A51: 207 | B51: FILMBESIKT | C51: Filmning/besiktning | D51: RENH | E51: EXT | F51: 1 | G51: KVAN | H51: Filmning/besiktning | K51: 113.6 | L51: 44927 | M51: 0 | O51: - | P51: 1 | Q51: TIMT
A52: 20 | B52: FJ | C52: FJÄRRVÄRME | D52: VA | E52: FJ | F52: 1 | G52: FÖRB | H52: Fjärrvärme | K52: 424 | L52: 37987 | M52: 0 | O52: - | P52: 1
A53: 94 | B53: FRAMKAVG | C53: Framkörningsavgift | D53: RENH | E53: SLAM | F53: 1 | G53: KVAN | H53: Framkörningsavgift | K53: 652 | L53: 45658 | M53: 0 | O53: - | P53: 1 | Q53: ANTL
...

Sheet Taxa_till_edp
A1: intRecnum | B1: strTaxekod | C1: strTaxebenamning | D1: strProdukt | E1: strDelProdukt | F1: bytDelradnr | G1: strFaktor | H1: strTaxedelAvser | I1: strEntreprenorkod | J1: strRenhDistrKod | K1: curNuvarandePris | L1: datNuvarandePrisDatum | M1: bolPrisPerTomning | N1: strAvvikandeFormel | O1: bolPriserInklMoms | P1: bytMomskod | Q1: strFormel

Sheet QA Word-Excel struktur
A1: Kontroll | B1: Status
A2: Källfil Word | B2: Förslag till taxestruktur mall ASN 2026-03-13 v2(2).docx
A3: Källfil Excel | B3: Avfallstaxa_redigerbar_korrigerad_tom_2_2_6(1).xlsx
A4: Åtgärd | B4: Taxepunkter har byggts om så att varje prisfält i Word motsvarar en egen rad i Excel.
A5: Antal rader i Taxepunkter efter korrigering | B5: 367
A7: Tillagda/korrigerade huvudområden | B7: Kommentar
A8: §2.2.6 | B8: Saknad paragraf byggd med samtliga 15 prispunkter.
A9: §2.2.7 | B9: Saknad paragraf byggd med 3 prispunkter.
A10: §2.2.1–§2.2.2 | B10: Rader delade upp per hämtningsintervall enligt Word.
A11: §2.4.1–§2.4.11 | B11: Tidigare §2.6.* och separata 2.4/2.5 har byggts om enligt Word-numrering.
A12: §2.5.1 | B12: Budning för fastighetsnära hämtning flyttad från tidigare §2.7.4 till Word-strukturen.
A13: §3–§5 | B13: Saknade rader för tillägg per m3, extra tank/brunn, latrin, fosforfilter och fettavskiljare har lagts till enligt Word.
A14: §6.1.1–§6.1.4 | B14: ÅVC-struktur byggd enligt Word-numrering; befintliga §6- och tidigare §2.7-rader har bevarats under §6.
A16: Obs | B16: Taxakod/pris har bara bevarats där befintlig rad kunde matchas. Nya rader saknar taxakod/pris tills ni fyller i dessa.

Sheet Taxa_Saknas
A1: Källparagraf | B1: Källpunkt | C1: Rad i Taxepunkter | D1: Wordtext | E1: Status | F1: Matchmetod | G1: FöreslagenTaxekod | H1: intRecnum | I1: Taxepunkt | J1: strTaxekod | K1: strTaxebenamning | L1: strProdukt | M1: strDelProdukt | N1: bytDelradnr | O1: strFaktor | P1: strTaxedelAvser | Q1: strEntreprenorkod | R1: strRenhDistrKod | S1: curNuvarandePris | T1: datNuvarandePrisDatum | U1: bolPrisPerTomning | V1: strAvvikandeFormel | W1: bolPriserInklMoms | X1: bytMomskod | Y1: strFormel
A194: =IF($C194="","",INDEX(Taxepunkter!$A:$A,$C194)) | D194: =IF($C194="","",_xludf.TEXTJOIN(" ",TRUE,INDEX(Taxepunkter!$C:$C,$C194),INDEX(Taxepunkter!$D:$D,$C194))) | E194: =IF($C194="","","Saknas i EDP – föreslagen ny taxa") | F194: =IF($C194="","","Automatiserad mall: fyll Rad i Taxepunkter och FöreslagenTaxekod") | H194: =IF($C194="","",$C194) | I194: =IF($C194="","",INDEX(Taxepunkter!$B:$B,$C194)&" / "&INDEX(Taxepunkter!$C:$C,$C194)) | J194: =IF($G194="","",$G194) | K194: =IF($C194="","",INDEX(Taxepunkter!$C:$C,$C194)&IF(INDEX(Taxepunkter!$D:$D,$C194)="","",". "&INDEX(Taxepunkter!$D:$D,$C194))) | L194: =IF($C194="","","RENH") | M194: =IF($C194="","","HUSH") | N194: =IF($C194="","",1) | O194: =IF($C194="","","ÅRKV") | P194: =IF($C194="","",_xludf.TEXTJOIN(" ",TRUE,INDEX(Taxepunkter!$C:$C,$C194),INDEX(Taxepunkter!$D:$D,$C194))) | U194: =IF($C194="","",0) | W194: =IF($C194="","","-") | X194: =IF($C194="","",1) | Y194: =IF($C194="","","ANTB")
A195: =IF($C195="","",INDEX(Taxepunkter!$A:$A,$C195)) | D195: =IF($C195="","",_xludf.TEXTJOIN(" ",TRUE,INDEX(Taxepunkter!$C:$C,$C195),INDEX(Taxepunkter!$D:$D,$C195))) | E195: =IF($C195="","","Saknas i EDP – föreslagen ny taxa") | F195: =IF($C195="","","Automatiserad mall: fyll Rad i Taxepunkter och FöreslagenTaxekod") | H195: =IF($C195="","",$C195) | I195: =IF($C195="","",INDEX(Taxepunkter!$B:$B,$C195)&" / "&INDEX(Taxepunkter!$C:$C,$C195)) | J195: =IF($G195="","",$G195) | K195: =IF($C195="","",INDEX(Taxepunkter!$C:$C,$C195)&IF(INDEX(Taxepunkter!$D:$D,$C195)="","",". "&INDEX(Taxepunkter!$D:$D,$C195))) | L195: =IF($C195="","","RENH") | M195: =IF($C195="","","HUSH") | N195: =IF($C195="","",1) | O195: =IF($C195="","","ÅRKV") | P195: =IF($C195="","",_xludf.TEXTJOIN(" ",TRUE,INDEX(Taxepunkter!$C:$C,$C195),INDEX(Taxepunkter!$D:$D,$C195))) | U195: =IF($C195="","",0) | W195: =IF($C195="","","-") | X195: =IF($C195="","",1) | Y195: =IF($C195="","","ANTB")
A196: =IF($C196="","",INDEX(Taxepunkter!$A:$A,$C196)) | D196: =IF($C196="","",_xludf.TEXTJOIN(" ",TRUE,INDEX(Taxepunkter!$C:$C,$C196),INDEX(Taxepunkter!$D:$D,$C196))) | E196: =IF($C196="","","Saknas i EDP – föreslagen ny taxa") | F196: =IF($C196="","","Automatiserad mall: fyll Rad i Taxepunkter och FöreslagenTaxekod") | H196: =IF($C196="","",$C196) | I196: =IF($C196="","",INDEX(Taxepunkter!$B:$B,$C196)&" / "&INDEX(Taxepunkter!$C:$C,$C196)) | J196: =IF($G196="","",$G196) | K196: =IF($C196="","",INDEX(Taxepunkter!$C:$C,$C196)&IF(INDEX(Taxepunkter!$D:$D,$C196)="","",". "&INDEX(Taxepunkter!$D:$D,$C196))) | L196: =IF($C196="","","RENH") | M196: =IF($C196="","","HUSH") | N196: =IF($C196="","",1) | O196: =IF($C196="","","ÅRKV") | P196: =IF($C196="","",_xludf.TEXTJOIN(" ",TRUE,INDEX(Taxepunkter!$C:$C,$C196),INDEX(Taxepunkter!$D:$D,$C196))) | U196: =IF($C196="","",0) | W196: =IF($C196="","","-") | X196: =IF($C196="","",1) | Y196: =IF($C196="","","ANTB")
A197: =IF($C197="","",INDEX(Taxepunkter!$A:$A,$C197)) | D197: =IF($C197="","",_xludf.TEXTJOIN(" ",TRUE,INDEX(Taxepunkter!$C:$C,$C197),INDEX(Taxepunkter!$D:$D,$C197))) | E197: =IF($C197="","","Saknas i EDP – föreslagen ny taxa") | F197: =IF($C197="","","Automatiserad mall: fyll Rad i Taxepunkter och FöreslagenTaxekod") | H197: =IF($C197="","",$C197) | I197: =IF($C197="","",INDEX(Taxepunkter!$B:$B,$C197)&" / "&INDEX(Taxepunkter!$C:$C,$C197)) | J197: =IF($G197="","",$G197) | K197: =IF($C197="","",INDEX(Taxepunkter!$C:$C,$C197)&IF(INDEX(Taxepunkter!$D:$D,$C197)="","",". "&INDEX(Taxepunkter!$D:$D,$C197))) | L197: =IF($C197="","","RENH") | M197: =IF($C197="","","HUSH") | N197: =IF($C197="","",1) | O197: =IF($C197="","","ÅRKV") | P197: =IF($C197="","",_xludf.TEXTJOIN(" ",TRUE,INDEX(Taxepunkter!$C:$C,$C197),INDEX(Taxepunkter!$D:$D,$C197))) | U197: =IF($C197="","",0) | W197: =IF($C197="","","-") | X197: =IF($C197="","",1) | Y197: =IF($C197="","","ANTB")
A198: =IF($C198="","",INDEX(Taxepunkter!$A:$A,$C198)) | D198: =IF($C198="","",_xludf.TEXTJOIN(" ",TRUE,INDEX(Taxepunkter!$C:$C,$C198),INDEX(Taxepunkter!$D:$D,$C198))) | E198: =IF($C198="","","Saknas i EDP – föreslagen ny taxa") | F198: =IF($C198="","","Automatiserad mall: fyll Rad i Taxepunkter och FöreslagenTaxekod") | H198: =IF($C198="","",$C198) | I198: =IF($C198="","",INDEX(Taxepunkter!$B:$B,$C198)&" / "&INDEX(Taxepunkter!$C:$C,$C198)) | J198: =IF($G198="","",$G198) | K198: =IF($C198="","",INDEX(Taxepunkter!$C:$C,$C198)&IF(INDEX(Taxepunkter!$D:$D,$C198)="","",". "&INDEX(Taxepunkter!$D:$D,$C198))) | L198: =IF($C198="","","RENH") | M198: =IF($C198="","","HUSH") | N198: =IF($C198="","",1) | O198: =IF($C198="","","ÅRKV") | P198: =IF($C198="","",_xludf.TEXTJOIN(" ",TRUE,INDEX(Taxepunkter!$C:$C,$C198),INDEX(Taxepunkter!$D:$D,$C198))) | U198: =IF($C198="","",0) | W198: =IF($C198="","","-") | X198: =IF($C198="","",1) | Y198: =IF($C198="","","ANTB")
A199: =IF($C199="","",INDEX(Taxepunkter!$A:$A,$C199)) | D199: =IF($C199="","",_xludf.TEXTJOIN(" ",TRUE,INDEX(Taxepunkter!$C:$C,$C199),INDEX(Taxepunkter!$D:$D,$C199))) | E199: =IF($C199="","","Saknas i EDP – föreslagen ny taxa") | F199: =IF($C199="","","Automatiserad mall: fyll Rad i Taxepunkter och FöreslagenTaxekod") | H199: =IF($C199="","",$C199) | I199: =IF($C199="","",INDEX(Taxepunkter!$B:$B,$C199)&" / "&INDEX(Taxepunkter!$C:$C,$C199)) | J199: =IF($G199="","",$G199) | K199: =IF($C199="","",INDEX(Taxepunkter!$C:$C,$C199)&IF(INDEX(Taxepunkter!$D:$D,$C199)="","",". "&INDEX(Taxepunkter!$D:$D,$C199))) | L199: =IF($C199="","","RENH") | M199: =IF($C199="","","HUSH") | N199: =IF($C199="","",1) | O199: =IF($C199="","","ÅRKV") | P199: =IF($C199="","",_xludf.TEXTJOIN(" ",TRUE,INDEX(Taxepunkter!$C:$C,$C199),INDEX(Taxepunkter!$D:$D,$C199))) | U199: =IF($C199="","",0) | W199: =IF($C199="","","-") | X199: =IF($C199="","",1) | Y199: =IF($C199="","","ANTB")
A200: =IF($C200="","",INDEX(Taxepunkter!$A:$A,$C200)) | D200: =IF($C200="","",_xludf.TEXTJOIN(" ",TRUE,INDEX(Taxepunkter!$C:$C,$C200),INDEX(Taxepunkter!$D:$D,$C200))) | E200: =IF($C200="","","Saknas i EDP – föreslagen ny taxa") | F200: =IF($C200="","","Automatiserad mall: fyll Rad i Taxepunkter och FöreslagenTaxekod") | H200: =IF($C200="","",$C200) | I200: =IF($C200="","",INDEX(Taxepunkter!$B:$B,$C200)&" / "&INDEX(Taxepunkter!$C:$C,$C200)) | J200: =IF($G200="","",$G200) | K200: =IF($C200="","",INDEX(Taxepunkter!$C:$C,$C200)&IF(INDEX(Taxepunkter!$D:$D,$C200)="","",". "&INDEX(Taxepunkter!$D:$D,$C200))) | L200: =IF($C200="","","RENH") | M200: =IF($C200="","","HUSH") | N200: =IF($C200="","",1) | O200: =IF($C200="","","ÅRKV") | P200: =IF($C200="","",_xludf.TEXTJOIN(" ",TRUE,INDEX(Taxepunkter!$C:$C,$C200),INDEX(Taxepunkter!$D:$D,$C200))) | U200: =IF($C200="","",0) | W200: =IF($C200="","","-") | X200: =IF($C200="","",1) | Y200: =IF($C200="","","ANTB")

Sheet Taxekod_Tolkning
A1: Koddel | B1: Typ | C1: Betydelse | D1: Exempel | E1: Första förekomst | F1: Källa | G1: Status | H1: Kommentar
A2: KÄ | B2: Prefix | C2: Kärl | D2: KÄ240RM26 | E2: Taxa_från_edp rad 234 / strTaxekod KÄ240RM26 | F2: strTaxekod + strTaxebenamning | G2: Bekräftad
A3: MB | B3: Prefix | C3: Markbehållare eller underjordsbehållare | D3: MB3200RE26 | E3: Taxa_från_edp rad 211 / 271 | F3: strTaxebenamning + användarbekräftelse | G3: Bekräftad | H3: Kan omfatta både mark- och underjordsbehållare.
A4: BTMR | B4: Kodstruktur | C4: Bottentömmande behållare, mat-/restavfall | D4: BTMRFV | E4: Taxa_Saknas / föreslagen struktur | F4: Användarbekräftelse | G4: Bekräftad | H4: Används för nya föreslagna taxor när EDP-träff saknas.
A5: LVRE | B5: Kodstruktur | C5: Lastväxlarflak, restavfall | D5: LVREFV | E5: Taxa_Saknas / föreslagen struktur | F5: Användarbekräftelse | G5: Bekräftad | H5: Används för nya föreslagna taxor när EDP-träff saknas.
A6: RM | B6: Avfallsslag | C6: Rest-/matavfall | D6: KÄ240RM26 | E6: Taxa_från_edp rad 234 / strTaxekod KÄ240RM26 | F6: strTaxebenamning: rest/matavfall | G6: Bekräftad
A7: RK | B7: Avfallsslag | C7: Restavfall/kompost | D7: KÄ240RK26 | E7: Taxa_från_edp rad 232 / strTaxekod KÄ240RK26 | F7: strTaxebenamning: restavfall/kompost | G7: Bekräftad
A8: RE | B8: Avfallsslag | C8: Restavfall | D8: KÄ370RE26FV | E8: Taxa_från_edp rad 242 / strTaxekod KÄ370RE26FV | F8: strTaxebenamning + strTaxedelAvser | G8: Bekräftad
A9: MA | B9: Avfallsslag | C9: Matavfall | D9: KÄ140MA52FV | E9: Taxa_från_edp rad 221 / strTaxekod KÄ140MA52FV | F9: strTaxebenamning + strTaxedelAvser | G9: Bekräftad
A10: TI | B10: Avfallsslag | C10: Tidningar/returpapper | D10: KÄ190TI26FV | E10: Taxa_Saknas / föreslagen struktur | F10: Användarbekräftelse | G10: Bekräftad | H10: Används där EDP-träff saknas för tidningar/returpapper.
A11: FP | B11: Avfallsslag | C11: Förpackningar | D11: KÄ370FP26FV | E11: Taxa_Saknas / föreslagen struktur | F11: Användarbekräftelse | G11: Bekräftad | H11: Används där EDP-träff saknas för förpackningar.
A12: XRM | B12: Avfallsslag/kärltyp | C12: Extrakärl rest-/matavfall | D12: KÄ190XRM26 | E12: Taxa_från_edp rad 226 / strTaxekod KÄ190XRM26 | F12: strTaxebenamning: extrakärl, rest/matavfall | G12: Bekräftad
A13: 140 | B13: Volym | C13: 140 liter | D13: KÄ140MA26FV | E13: Taxa_från_edp rad 216 / strTaxekod KÄ140MA26FV | F13: strTaxebenamning | G13: Bekräftad
A14: 190 | B14: Volym | C14: 190 liter / 120–190 liter för extrakärl | D14: KÄ190XRM26 | E14: Taxa_från_edp rad 226 / strTaxekod KÄ190XRM26 | F14: strTaxebenamning | G14: Bekräftad
A15: 240 | B15: Volym | C15: 240 liter | D15: KÄ240RM26 | E15: Taxa_från_edp rad 234 / strTaxekod KÄ240RM26 | F15: strTaxebenamning | G15: Bekräftad
A16: 370 | B16: Volym | C16: 370 liter | D16: KÄ370RE26FV | E16: Taxa_från_edp rad 242 / strTaxekod KÄ370RE26FV | F16: strTaxebenamning | G16: Bekräftad
A17: 660 | B17: Volym | C17: 660 liter | D17: KÄ660RE26FV | E17: Taxa_från_edp rad 254 / strTaxekod KÄ660RE26FV | F17: strTaxebenamning | G17: Bekräftad
A18: 26 | B18: Frekvens | C18: Var 14:e dag / 26 tömningar per år | D18: KÄ240RM26 | E18: Taxa_från_edp rad 234 / strTaxekod KÄ240RM26 | F18: strTaxebenamning | G18: Bekräftad
A19: 52 | B19: Frekvens | C19: Varje vecka / 52 tömningar per år | D19: KÄ240RM52FV | E19: Taxa_från_edp rad 31 / strTaxekod KÄ240RM52FV | F19: strTaxebenamning | G19: Bekräftad
A20: 12 | B20: Frekvens | C20: Månadsvis / 12 tömningar per år | D20: KÄ240RM12FV | E20: Taxa_Saknas / föreslagen struktur | F20: Härledd från kodmönster och Word | G20: Härledd | H20: Finns inte som säker EDP-träff i genomgången hittills.
A21: FRI | B21: Suffix | C21: Fritidshus | D21: KÄ240RM26FRI | E21: Taxa_från_edp rad 236 / strTaxekod KÄ240RM26FRI | F21: strTaxebenamning | G21: Bekräftad
A22: FV | B22: Suffix | C22: Flerbostadshus eller verksamhet | D22: KÄ660RE52FV | E22: Taxa_från_edp rad 259 / strTaxekod KÄ660RE52FV | F22: strTaxebenamning: FLB/VHT + användarbekräftelse | G22: Bekräftad | H22: Samma FV-taxekod kan användas både för flerbostadshus och verksamhet om övriga villkor stämmer.
A23: FLB | B23: Förkortning i benämning | C23: Flerbostadshus | D23: FLB/VHT | E23: Taxa_från_edp, flera rader | F23: strTaxebenamning | G23: Bekräftad | H23: Förekommer i strTaxebenamning, inte nödvändigtvis som egen koddel.
A24: VHT | B24: Förkortning i benämning | C24: Verksamhet | D24: FLB/VHT | E24: Taxa_från_edp, flera rader | F24: strTaxebenamning | G24: Bekräftad | H24: Förekommer i strTaxebenamning, inte nödvändigtvis som egen koddel.
A25: SL | B25: Prefix/kategori | C25: Slam | D25: SLBUDFOS | E25: Taxa_från_edp rad 133 / strTaxekod SLBUDFOS | F25: strDelProdukt + strTaxebenamning | G25: Bekräftad
A26: ÅVC | B26: Kategori | C26: Återvinningscentral | D26: ASBEST | E26: Taxa_från_edp rad 66 / strDelProdukt ÅVC | F26: strDelProdukt | G26: Bekräftad
A27: TÖM | B27: Koddel | C27: Tömning | D27: MB3200TÖM | E27: Taxa_från_edp rad 211 / strTaxekod MB3200TÖM | F27: strTaxebenamning + strTaxedelAvser | G27: Bekräftad
A28: KVAN | B28: strFaktor | C28: Kvantitet | D28: KVAN | E28: Taxa_från_edp rad 2 | F28: kvantitetskoder + strFaktor | G28: Bekräftad
A29: ÅRKV | B29: strFaktor | C29: Årskvantitet | D29: ÅRKV | E29: Taxa_från_edp rad 216 | F29: kvantitetskoder + strFaktor | G29: Bekräftad
A30: ÅRPR | B30: strFaktor | C30: Årspris | D30: ÅRPR | E30: Taxa_från_edp VA-rader | F30: kvantitetskoder + strFaktor | G30: Bekräftad
A31: FÖRB | B31: strFaktor | C31: Förbrukning | D31: FÖRB | E31: Taxa_från_edp VA-rader | F31: kvantitetskoder + strFaktor | G31: Bekräftad
A32: UPFÖ | B32: strFaktor | C32: Uppskattad förbrukning | D32: UPFÖ | E32: Taxa_från_edp VA-rader | F32: kvantitetskoder + strFaktor | G32: Bekräftad
A33: ANTB | B33: strFormel | C33: Antal behållare | D33: ANTB | E33: Taxa_från_edp, kärlrader | F33: kvantitetskoder + strFormel | G33: Bekräftad
A34: ANTL | B34: strFormel | C34: Övriga antal / antal tillfällen | D34: ANTL | E34: Taxa_från_edp, t.ex. FELSORT | F34: kvantitetskoder + strFormel | G34: Bekräftad
A35: FAST | B35: strFormel | C35: Fast avgift | D35: FAST | E35: Taxa_från_edp rad 215 GEMUPPFRI | F35: kvantitetskoder + strFormel | G35: Bekräftad
A36: LÄGH | B36: strFormel | C36: Lägenheter | D36: LÄGH | E36: Taxa_från_edp VA-rader | F36: kvantitetskoder + strFormel | G36: Bekräftad
... A41: KBMS | B41: strFormel | C41: Kubikmeter slam | D41: KBMS | E41: Taxa_från_edp slamrader | F41: kvantitetskoder + strFormel | G41: Bekräftad
A45: DH | B45: Suffix | C45: Detaljhandel med beviljad hantering av kommunalt avfall | D45: KÄ240RM26DH | E45: Taxa_Saknas / föreslagen struktur | F45: Användarbekräftelse | G45: Bekräftad | H45: Används för §2.2.6. Ska inte använda FV eftersom detaljhandel inte räknas som vanlig verksamhet/flerbostad i denna taxa.
A49: MBRMFPFV | B49: Föreslagen kodstruktur | C49: Bottentömmande/markbehållare för mat-/restavfall och förpackningar, flerbostad/verksamhet | D49: MBRMFPFV | E49: Taxa_Saknas §2.2.4 | F49: Projektregel MB + Word | G49: Föreslagen | H49: Ersätter tidigare BTMR-struktur.
A50: MBRMFP2VFV | B50: Föreslagen kodstruktur | C50: Tillägg för två tömningar per vecka för bottentömmande/markbehållare, flerbostad/verksamhet | D50: MBRMFP2VFV | E50: Taxa_Saknas §2.2.4 | F50: Projektregel MB + Word | G50: Föreslagen
...

Sheet Källa_Prislista_DH
A1: Prislista ASN – kärltömning och kärlhyra
A2: Avser marknadstjänster och/eller kommunens andrahandsansvar. Tjänsten ska särredovisas och inte belasta avfallstaxan eller taxekollektivet.
A4: Beräkningsgrund | B4: Full självkostnad med intern ersättning till taxekollektivet
A5: Moms | B5: 0.25 | C5: Ändra moms här
A7: Post | B7: Exkl. moms | C7: Inkl. moms
A8: Intern kalkyltimme sopbil inkl. chaufför och OH | B8: 1500 | C8: 1875
A9: Kärltömning 140–240 liter, ordinarie tur/intervall | B9: 125 | C9: 156.25
A10: Kärltömning 370 liter, ordinarie tur/intervall | B10: 145 | C10: 181.25
A11: Kärltömning 660 liter, ordinarie tur/intervall | B11: 165 | C11: 206.25
A12: Extra/avvikande tömning utanför planerad rutt | B12: 1500 | C12: 1875
A13: Kärlhyra 140 liter | B13: 25 | C13: 31.25
A14: Kärlhyra 190 liter | B14: 30 | C14: 37.5
A15: Kärlhyra 240 liter | B15: 35 | C15: 43.75
A16: Kärlhyra 370 liter | B16: 50 | C16: 62.5
A17: Kärlhyra 660 liter | B17: 85 | C17: 106.25
A18: Utkörning/utställning av kärl 140–240 | B18: 300 | C18: 375
A19: Utkörning/utställning av kärl 370–660 | B19: 450 | C19: 562.5
... A23: Restavfall | B23: 4200 | C23: 5250
A24: ABP | B24: Debiteras separat enligt faktisk kostnad | C24: Debiteras separat enligt faktisk kostnad
A27: Regel | B27: DH-priser är unika för detaljhandel och får inte användas i beräkningsmodeller för andra taxor.
A28: Källa | B28: Prislista DH.xlsx

Sheet Källa_Kvantitetskoder
A1: Kod | B1: Tolkning | C1: Källa/kommentar
A2: KVAN | B2: Kvantitet | C2: Användarens fil/uppgift + Taxa_från_edp strFaktor
A3: ÅRKV | B3: Årskvantitet | C3: Användarens fil/uppgift + Taxa_från_edp strFaktor
A4: ÅRPR | B4: Årspris | C4: Kvantitetskoder + Taxa_från_edp strFaktor
A5: FÖRB | B5: Förbrukning | C5: Användarens uppgift + Taxa_från_edp strFaktor
A6: UPFÖ | B6: Uppskattad förbrukning | C6: Kvantitetskoder + Taxa_från_edp strFaktor
A7: ANTB | B7: Antal behållare | C7: Taxa_från_edp strFormel
A8: ANTL | B8: Övriga antal / antal tillfällen | C8: Taxa_från_edp strFormel
A9: VIKG | B9: Vikt i kilo | C9: Taxa_från_edp strFormel
A10: DR10 | B10: Dragväg 1,5–10 meter | C10: Taxa_från_edp strFormel/strTaxedelAvser
A11: DR20 | B11: Dragväg 10,1–20 meter | C11: Taxa_från_edp strFormel/strTaxedelAvser
A12: LÄGH | B12: Lägenheter | C12: Taxa_från_edp strFormel
... A15: KBMS | B15: Kubikmeter slam | C15: Taxa_från_edp strFormel

Sheet 01_Projektöversikt
A1: Avfallstaxa – självdokumenterande masterfil
A2: Syfte | B2: Bygga och kvalitetssäkra Taxepunkter från Word, EDP och kompletterande prislistor.
A3: Fas 1 | B3: Word → Excel: pågår. Word styr struktur, Taxepunkter byggs successivt, Taxa_Saknas byggs successivt.
A4: Fas 2 | B4: Excel → Word: ej påbörjad. Ska hanteras separat senare. Regler för Fas 1 får inte blandas med Fas 2.
A5: Status | B5: Taxepunkter är under uppbyggnad. Arbetet är genomfört till och med §2.2.6 med kända justeringar.
A6: Viktig princip | B6: Arbetsboken ska kunna återanvändas med ny Taxa_från_edp från annat verksamhetssystem genom att läsa regler, källdokument, lexikon och beslutslogg.

Sheet 02_Projektregler
A1: ID | B1: Regel | C1: Beskrivning
A2: R001 | B2: Fasindelning | C2: Projektet består av två separata faser: Fas 1 Word → Excel och Fas 2 Excel → Word. De får inte blandas.
A3: R002 | B3: Word styr struktur i Fas 1 | C3: Alla taxepunkter, rader och kostnadsfria tjänster som finns i Word ska finnas i Taxepunkter.
A4: R003 | B4: Taxepunkter byggs successivt | C4: Taxepunkter är en arbetsflik under uppbyggnad och får inte ersättas med importdata.
A5: R004 | B5: Taxakod | C5: Kolumn Taxakod innehåller endast bekräftad exakt strTaxekod från Taxa_från_edp.
A6: R005 | B6: Ingen påhittad Taxakod | C6: Om match finns i Taxa_från_edp används exakt strTaxekod. Hitta inte på egen kod om EDP-kod finns.
A7: R006 | B7: Föreslagen Taxa | C7: Visar Taxakod om den är bekräftad, annars föreslagen taxa från Taxa_Saknas.
A8: R007 | B8: Aktuellt pris | C8: Aktuellt pris (exkl moms) hämtas alltid från Taxa_från_edp och får aldrig redigeras manuellt.
A9: R008 | B9: Föreslaget pris | C9: Får fyllas manuellt/beräknas som arbetspris när Aktuellt pris saknas. Detta är inte EDP-pris.
A10: R009 | B10: DH-priser | C10: Prislista DH används endast för detaljhandel och får aldrig användas för beräkningsmodeller för andra taxor.
A11: R010 | B11: Taxa_Saknas | C11: Innehåller saknade eller föreslagna taxor med samma EDP-kolumner som Taxa_från_edp samt arbetskolumner.
A12: R011 | B12: intRecnum i Taxa_Saknas | C12: intRecnum = radnummer i Taxepunkter för felsökning, inte EDP:s original-ID.
... A25: R024 | B25: Vanliga taxerader i Taxepunkter | C25: Rader där A:E innehåller uppdelad information, t.ex. Paragraf, Paragrafnamn, Taxapunkt, Variant och Enhet, ska inte vara sammanslagna och A:E ska ha vit bakgrund.

Sheet 03_Arbetsflöde
A1: Steg | B1: Arbetsmoment | C1: Beskrivning
A2: 1 | B2: Läs Projektöversikt | C2: Identifiera om arbetet gäller Fas 1 Word→Excel eller Fas 2 Excel→Word.
A3: 2 | B3: Läs Projektregler | C3: Följ reglerna innan några ändringar görs.
A4: 3 | B4: Läs Källdokument | C4: Kontrollera vilka importflikar och externa filer som krävs.
A5: 4 | B5: Läs Taxekod_Tolkning | C5: Använd lexikonet för prefix, suffix, koddelar, strFaktor och strFormel.
A6: 5 | B6: Importera/ersätt Taxa_från_edp | C6: Om ny EDP-export används ska endast importfliken bytas, inte arbetsflikarna.
A7: 6 | B7: Kontrollera Word mot Taxepunkter | C7: Lägg till saknade rader från Word, inklusive kostnadsfria rader.
A8: 7 | B8: Matcha mot Taxa_från_edp | C8: Använd matchningsordningen strTaxekod → strTaxebenamning → strTaxedelAvser → strFaktor.
A9: 8 | B9: Uppdatera Taxa_Saknas | C9: Alla saknade/osäkra taxor ska dokumenteras med intRecnum = Taxepunkter-rad.
A10: 9 | B10: Uppdatera Föreslagen Taxa | C10: Kolumnen hämtar bekräftad Taxakod eller förslag från Taxa_Saknas.
A11: 10 | B11: Fyll Föreslaget pris vid behov | C11: Aktuellt pris får aldrig ändras. Föreslaget pris används bara som arbetspris.
A12: 11 | B12: Dokumentera beslut | C12: Uppdatera Beslutslogg och Kontrollrapport.
A13: 12 | B13: Vänta med Excel→Word | C13: Prisöverföring till Word hanteras i senare separat fas.

Sheet 04_Källdokument
A1: Källa/flik | B1: Obligatorisk | C1: Funktion | D1: Får ersättas vid ny körning | E1: Kommentar
A2: Word taxedokument (.docx) | B2: Ja | C2: Juridisk/strukturell källa för Taxepunkter | D2: Ja | E2: Ska importeras/läsas vid ny taxemall. Nuvarande Word ligger ej som komplett filflik i Excel.
A3: Taxa_från_edp | B3: Ja | C3: Bekräftade taxekoder, benämningar, faktorer, formler och priser | D3: Ja | E3: Enda källa för Aktuellt pris. Får bytas mot ny export.
A4: Källa_Prislista_DH | B4: Ja om DH finns | C4: Unik prislista för detaljhandel | D4: Ja | E4: Får endast användas för DH och aldrig för andra beräkningsmodeller.
A5: Källa_Kvantitetskoder | B5: Ja | C5: Referens för strFaktor/strFormel | D5: Ja | E5: Används för tolkning, inte för pris.
A6: Taxepunkter | B6: Ja | C6: Arbetsflik som byggs från Word + EDP | D6: Nej | E6: Under uppbyggnad och ska inte ersättas.
A7: Taxa_Saknas | B7: Ja | C7: Saknade/föreslagna taxor | D7: Nej | E7: Under uppbyggnad och ska inte ersättas.
A8: Taxekod_Tolkning | B8: Ja | C8: Lexikon över koddelar | D8: Nej | E8: Byggs successivt.
A9: Projektregler/Arbetsflöde/Beslutslogg | B9: Ja | C9: Självdokumentation | D9: Nej | E9: Behövs för framtida promptning.

Sheet 06_Prompt_ChatGPT
A1: Instruktion till ChatGPT för fortsatt arbete
A2: 1. Läs flikarna 01_Projektöversikt, 02_Projektregler, 03_Arbetsflöde, 04_Källdokument, Taxekod_Tolkning och Beslutslogg innan du ändrar något.
A3: 2. Arbetet är i Fas 1 Word → Excel tills annat uttryckligen anges. Regler för Excel → Word ska inte användas ännu.
A4: 3. Taxepunkter är en arbetsflik under uppbyggnad. Den ska byggas från Word och Taxa_från_edp, inte ersättas.
A5: 4. Alla rader i Word, även kostnadsfria rader, ska finnas i Taxepunkter.
A6: 5. Taxakod får endast innehålla bekräftad exakt strTaxekod från Taxa_från_edp.
A7: 6. Aktuellt pris får aldrig redigeras manuellt. Det hämtas från Taxa_från_edp.
A8: 7. Föreslagen Taxa visar Taxakod om bekräftad, annars förslag från Taxa_Saknas.
A9: 8. Föreslaget pris kan användas som arbetspris när Aktuellt pris saknas. DH-priser får bara användas för DH.
A10: 9. Matcha taxor via strTaxekod, strTaxebenamning, strTaxedelAvser, strFaktor och strFormel.
A11: 10. Om taxan saknas: lägg i Taxa_Saknas med intRecnum = radnumret i Taxepunkter.
A12: 11. Uppdatera Taxekod_Tolkning när nya koddelar identifieras.
... A15: 14. Sätt aldrig Aktuellt pris manuellt till 0. Pris hämtas bara från Taxa_från_edp; använd Föreslaget pris endast som arbetskolumn vid behov.

Sheet 07_Word_export_senare
A1: Excel → Word är inte påbörjad
A2: Denna fas ska hanteras separat senare.
A3: Preliminära principer: Word-text får inte ändras, endast prisfält/XX kr ska uppdateras från rätt rad i Taxepunkter.
A4: Regler för Word → Excel får inte användas som regler för Excel → Word utan ny genomgång.

Sheet Projektstatus
