Workbook
Name Factors_TK00001: #REF!
Name Factors_TK00002: #REF!
Name Factors_TK00003: #REF!
Name Factors_TK00004: #REF!
Name Factors_TK00005: #REF!
Name Factors_TK00006: #REF!
Name Factors_TK00007: #REF!
Name Factors_TK00008: #REF!
Name Factors_TK00009: #REF!
Name Factors_TK00010: #REF!
Name Factors_TK00011: #REF!
Name Factors_TK00012: #REF!
Name Factors_TK00013: #REF!
Name Factors_TK00014: #REF!
Name Factors_TK00015: #REF!
Name Factors_TK00016: #REF!
Name Factors_TK00017: #REF!
Name Factors_TK00018: #REF!
Name Factors_TK00019: #REF!
Name Factors_TK00020: #REF!
Name Factors_TK00021: #REF!
Name Factors_TK00022: #REF!
Name Factors_TK00023: #REF!
Name Factors_TK00024: #REF!
Name Factors_TK00025: #REF!
Name Factors_TK00026: #REF!
Name Factors_TK00027: #REF!
Name Factors_TK00028: #REF!
Name Factors_TK00029: #REF!
Name Factors_TK00030: #REF!
Name Factors_TK00031: #REF!
Name Factors_TK00032: #REF!
Name Factors_TK00033: #REF!
Name Factors_TK00034: #REF!
Name Factors_TK00035: #REF!
Name Factors_TK00036: #REF!
Name Factors_TK00037: #REF!
Name Factors_TK00038: #REF!
Name Factors_TK00039: #REF!
Name Factors_TK00040: #REF!
Name Factors_TK00041: #REF!
Name Factors_TK00042: #REF!
Name Factors_TK00043: #REF!
Name Factors_TK00044: #REF!
Name Factors_TK00045: #REF!
Name Factors_TK00046: #REF!
Name Factors_TK00047: #REF!
Name Factors_TK00048: #REF!
Name Factors_TK00049: #REF!
Name Factors_TK00050: #REF!
Name Factors_TK00051: #REF!
Name Factors_TK00052: #REF!
Name Factors_TK00053: #REF!
Name Factors_TK00054: #REF!
Name Factors_TK00055: #REF!
Name Factors_TK00056: #REF!
Name Factors_TK00057: #REF!
Name Factors_TK00058: #REF!
Name Factors_TK00059: #REF!
Name Factors_TK00060: #REF!

Sheet Dashboard
A1: Dashboard – Intäktsmodell
A3: Total intäkt (kr) | B3: =SUM(Taxepunkter_Rådata!K:K) -> 0
A4: Antal taxerader (rådata) | B4: =COUNTA(Taxepunkter_Rådata!A:A)-1 -> 291
A5: Saknade priser (tomma) | B5: =COUNTIF(Taxepunkter_Rådata!J:J,"")-1 -> 1048551
A6: Andel ifyllda priser | B6: =IF(B4=0,"",1-(B5/B4)) -> -3602.268
A7: Rader med Antal > 0 men saknar pris | B7: =COUNTIFS(Taxepunkter_Rådata!I:I,">0",Taxepunkter_Rådata!J:J,"") -> 0
A9: Datakontroll | B9: =IF(Kontroller!C5="OK","OK","VARNING") -> VARNING

Sheet Taxepunkter
B1: XX kommuns avfallstaxa – fullständig kalkyl (intäkter)
B2: Matriser expanderas: en rad per (Taxapunkt × Variant). §6: Taxapunkt kompletteras med Avfallskod, UN-nummer blir Variant och Enhet tas från enhetskolumn.
A5: Paragraf | B5: Paragrafnamn | C5: Taxapunkt | D5: Variant | E5: Enhet | F5: Taxakod | G5: Föreslagen Taxa | H5: Taxabeskrivning | I5: Faktor | J5: Aktuellt pris (exkl m) | K5: Föreslaget pris | L5: Antal | M5: Pris kr (inkl.) | N5: Intäkt (kr) exkl
A6: §2.1 Grundavgift
A7: §2.1 | B7: Grundavgift | C7: En- och tvåbostadshus | E7: st/år | F7: GRUNDSMÅ | G7: =IF($F7<>"",$F7,IFERROR(_xlfn.XLOOKUP(ROW(),Taxa_Saknas!$H:$H,Taxa_Saknas!$G:$G),"")) -> GRUNDSMÅ | H7: =IF($F7<>"",IFERROR(_xlfn.XLOOKUP($F7,Taxa_från_edp!$B:$B,Taxa_från_edp!C:C),""),"") -> Grundavgift, småhus 1- och 2 familjshus | I7: =IF($F7<>"",IFERROR(_xlfn.XLOOKUP($F7,Taxa_från_edp!$B:$B,Taxa_från_edp!G:G),""),"") -> ÅRKV | J7: =IF($F7<>"",IFERROR(_xlfn.XLOOKUP($F7,Taxa_från_edp!$B:$B,Taxa_från_edp!K:K),""),"") -> 1320 | M7: =IFERROR(IF(J7<>"",J7*1.25,IF(K7<>"",K7*1.25,"")),"") -> 1650 | N7: =IFERROR(IF(J7<>"",L7*J7,IF(K7<>"",L7*K7,"")),"") -> 0
A8: §2.1 | B8: Grundavgift | C8: Fritidshus | E8: st/år | F8: GRUNDFRI | G8: =IF($F8<>"",$F8,IFERROR(_xlfn.XLOOKUP(ROW(),Taxa_Saknas!$H:$H,Taxa_Saknas!$G:$G),"")) -> GRUNDFRI | H8: =IF($F8<>"",IFERROR(_xlfn.XLOOKUP($F8,Taxa_från_edp!$B:$B,Taxa_från_edp!C:C),""),"") -> Grundavgift, fritidshus | I8: =IF($F8<>"",IFERROR(_xlfn.XLOOKUP($F8,Taxa_från_edp!$B:$B,Taxa_från_edp!G:G),""),"") -> ÅRKV | J8: =IF($F8<>"",IFERROR(_xlfn.XLOOKUP($F8,Taxa_från_edp!$B:$B,Taxa_från_edp!K:K),""),"") -> 1000 | M8: =IFERROR(IF(J8<>"",J8*1.25,IF(K8<>"",K8*1.25,"")),"") -> 1250 | N8: =IFERROR(IF(J8<>"",L8*J8,IF(K8<>"",L8*K8,"")),"") -> 0
A9: §2.1 | B9: Grundavgift | C9: Verksamhet | E9: st/år | F9: GRUNDVHT | G9: =IF($F9<>"",$F9,IFERROR(_xlfn.XLOOKUP(ROW(),Taxa_Saknas!$H:$H,Taxa_Saknas!$G:$G),"")) -> GRUNDVHT | H9: =IF($F9<>"",IFERROR(_xlfn.XLOOKUP($F9,Taxa_från_edp!$B:$B,Taxa_från_edp!C:C),""),"") -> Grundavgift, verksamheter | I9: =IF($F9<>"",IFERROR(_xlfn.XLOOKUP($F9,Taxa_från_edp!$B:$B,Taxa_från_edp!G:G),""),"") -> ÅRKV | J9: =IF($F9<>"",IFERROR(_xlfn.XLOOKUP($F9,Taxa_från_edp!$B:$B,Taxa_från_edp!K:K),""),"") -> 1000 | M9: =IFERROR(IF(J9<>"",J9*1.25,IF(K9<>"",K9*1.25,"")),"") -> 1250 | N9: =IFERROR(IF(J9<>"",L9*J9,IF(K9<>"",L9*K9,"")),"") -> 0
A10: §2.1 | B10: Grundavgift | C10: Lägenhet i flerbostadshus | E10: st/år | F10: GRUNDFLB | G10: =IF($F10<>"",$F10,IFERROR(_xlfn.XLOOKUP(ROW(),Taxa_Saknas!$H:$H,Taxa_Saknas!$G:$G),"")) -> GRUNDFLB | H10: =IF($F10<>"",IFERROR(_xlfn.XLOOKUP($F10,Taxa_från_edp!$B:$B,Taxa_från_edp!C:C),""),"") -> Grundavgift, del i flerbostadshus | I10: =IF($F10<>"",IFERROR(_xlfn.XLOOKUP($F10,Taxa_från_edp!$B:$B,Taxa_från_edp!G:G),""),"") -> ÅRKV | J10: =IF($F10<>"",IFERROR(_xlfn.XLOOKUP($F10,Taxa_från_edp!$B:$B,Taxa_från_edp!K:K),""),"") -> 640 | M10: =IFERROR(IF(J10<>"",J10*1.25,IF(K10<>"",K10*1.25,"")),"") -> 800 | N10: =IFERROR(IF(J10<>"",L10*J10,IF(K10<>"",L10*K10,"")),"") -> 0
A11: §2.1 | B11: Grundavgift | C11: Lägenhet för specialändamål | E11: st/år | F11: GRUNDSPEC | G11: =IF($F11<>"",$F11,IFERROR(_xlfn.XLOOKUP(ROW(),Taxa_Saknas!$H:$H,Taxa_Saknas!$G:$G),"")) -> GRUNDSPEC | H11: =IF($F11<>"",IFERROR(_xlfn.XLOOKUP($F11,Taxa_från_edp!$B:$B,Taxa_från_edp!C:C),""),"") | I11: =IF($F11<>"",IFERROR(_xlfn.XLOOKUP($F11,Taxa_från_edp!$B:$B,Taxa_från_edp!G:G),""),"") | J11: =IF($F11<>"",IFERROR(_xlfn.XLOOKUP($F11,Taxa_från_edp!$B:$B,Taxa_från_edp!K:K),""),"") | M11: =IFERROR(IF(J11<>"",J11*1.25,IF(K11<>"",K11*1.25,"")),"") | N11: =IFERROR(IF(J11<>"",L11*J11,IF(K11<>"",L11*K11,"")),"")
A12: §2.1 | B12: Grundavgift | C12: Anläggning | E12: st/år | F12: GRUNDANL | G12: =IF($F12<>"",$F12,IFERROR(_xlfn.XLOOKUP(ROW(),Taxa_Saknas!$H:$H,Taxa_Saknas!$G:$G),"")) -> GRUNDANL | H12: =IF($F12<>"",IFERROR(_xlfn.XLOOKUP($F12,Taxa_från_edp!$B:$B,Taxa_från_edp!C:C),""),"") | I12: =IF($F12<>"",IFERROR(_xlfn.XLOOKUP($F12,Taxa_från_edp!$B:$B,Taxa_från_edp!G:G),""),"") | J12: =IF($F12<>"",IFERROR(_xlfn.XLOOKUP($F12,Taxa_från_edp!$B:$B,Taxa_från_edp!K:K),""),"") | M12: =IFERROR(IF(J12<>"",J12*1.25,IF(K12<>"",K12*1.25,"")),"") | N12: =IFERROR(IF(J12<>"",L12*J12,IF(K12<>"",L12*K12,"")),"")
A13: §2.1 | B13: Grundavgift | C13: Säsongsbaserad uppställningsplats | E13: st/år | F13: GRUNDSÄS | G13: =IF($F13<>"",$F13,IFERROR(_xlfn.XLOOKUP(ROW(),Taxa_Saknas!$H:$H,Taxa_Saknas!$G:$G),"")) -> GRUNDSÄS | H13: =IF($F13<>"",IFERROR(_xlfn.XLOOKUP($F13,Taxa_från_edp!$B:$B,Taxa_från_edp!C:C),""),"") | I13: =IF($F13<>"",IFERROR(_xlfn.XLOOKUP($F13,Taxa_från_edp!$B:$B,Taxa_från_edp!G:G),""),"") | J13: =IF($F13<>"",IFERROR(_xlfn.XLOOKUP($F13,Taxa_från_edp!$B:$B,Taxa_från_edp!K:K),""),"") | M13: =IFERROR(IF(J13<>"",J13*1.25,IF(K13<>"",K13*1.25,"")),"") | N13: =IFERROR(IF(J13<>"",L13*J13,IF(K13<>"",L13*K13,"")),"")
A14: §2.1 | B14: Grundavgift | C14: Campingstuga/-lägenhet | E14: st/år | F14: GRUNDCAMP | G14: =IF($F14<>"",$F14,IFERROR(_xlfn.XLOOKUP(ROW(),Taxa_Saknas!$H:$H,Taxa_Saknas!$G:$G),"")) -> GRUNDCAMP | H14: =IF($F14<>"",IFERROR(_xlfn.XLOOKUP($F14,Taxa_från_edp!$B:$B,Taxa_från_edp!C:C),""),"") | I14: =IF($F14<>"",IFERROR(_xlfn.XLOOKUP($F14,Taxa_från_edp!$B:$B,Taxa_från_edp!G:G),""),"") | J14: =IF($F14<>"",IFERROR(_xlfn.XLOOKUP($F14,Taxa_från_edp!$B:$B,Taxa_från_edp!K:K),""),"") | M14: =IFERROR(IF(J14<>"",J14*1.25,IF(K14<>"",K14*1.25,"")),"") | N14: =IFERROR(IF(J14<>"",L14*J14,IF(K14<>"",L14*K14,"")),"")
A15: §2.1 | B15: Grundavgift | C15: Administrativ avgift vid beviljad dispens om uppehåll i hämtning eller eget omhändertagande av avfall under kommunalt ansvar | E15: st/år | F15: ADMINDISP | G15: =IF($F15<>"",$F15,IFERROR(_xlfn.XLOOKUP(ROW(),Taxa_Saknas!$H:$H,Taxa_Saknas!$G:$G),"")) -> ADMINDISP | H15: =IF($F15<>"",IFERROR(_xlfn.XLOOKUP($F15,Taxa_från_edp!$B:$B,Taxa_från_edp!C:C),""),"") | I15: =IF($F15<>"",IFERROR(_xlfn.XLOOKUP($F15,Taxa_från_edp!$B:$B,Taxa_från_edp!G:G),""),"") | J15: =IF($F15<>"",IFERROR(_xlfn.XLOOKUP($F15,Taxa_från_edp!$B:$B,Taxa_från_edp!K:K),""),"") | M15: =IFERROR(IF(J15<>"",J15*1.25,IF(K15<>"",K15*1.25,"")),"") | N15: =IFERROR(IF(J15<>"",L15*J15,IF(K15<>"",L15*K15,"")),"")
A16: §2.1 | G16: =IF($F16<>"",$F16,IFERROR(_xlfn.XLOOKUP(ROW(),Taxa_Saknas!$H:$H,Taxa_Saknas!$G:$G),"")) | H16: =IF($F16<>"",IFERROR(_xlfn.XLOOKUP($F16,Taxa_från_edp!$B:$B,Taxa_från_edp!C:C),""),"") | I16: =IF($F16<>"",IFERROR(_xlfn.XLOOKUP($F16,Taxa_från_edp!$B:$B,Taxa_från_edp!G:G),""),"") | J16: =IF($F16<>"",IFERROR(_xlfn.XLOOKUP($F16,Taxa_från_edp!$B:$B,Taxa_från_edp!K:K),""),"") | M16: =IFERROR(IF(J16<>"",J16*1.25,IF(K16<>"",K16*1.25,"")),"") | N16: =IFERROR(IF(J16<>"",L16*J16,IF(K16<>"",L16*K16,"")),"")
A17: §2.2.1 Hämtningsavgift per år för en- och tvåbostadshus | G17: =IF($F17<>"",$F17,IFERROR(_xlfn.XLOOKUP(ROW(),Taxa_Saknas!$H:$H,Taxa_Saknas!$G:$G),"")) | H17: =IF($F17<>"",IFERROR(_xlfn.XLOOKUP($F17,Taxa_från_edp!$B:$B,Taxa_från_edp!C:C),""),"") | I17: =IF($F17<>"",IFERROR(_xlfn.XLOOKUP($F17,Taxa_från_edp!$B:$B,Taxa_från_edp!G:G),""),"") | J17: =IF($F17<>"",IFERROR(_xlfn.XLOOKUP($F17,Taxa_från_edp!$B:$B,Taxa_från_edp!K:K),""),"") | M17: =IFERROR(IF(J17<>"",J17*1.25,IF(K17<>"",K17*1.25,"")),"") | N17: =IFERROR(IF(J17<>"",L17*J17,IF(K17<>"",L17*K17,"")),"")
A18: §2.2.1 | B18: Hämtningsavgift per år för en- och tvåbostadshus | C18: Kärl 240 l (mat-/restavfall) | D18: Hämtning var 14:e dag | E18: st/år | F18: KÄ240RM26 | G18: =IF($F18<>"",$F18,IFERROR(_xlfn.XLOOKUP(ROW(),Taxa_Saknas!$H:$H,Taxa_Saknas!$G:$G),"")) -> KÄ240RM26 | H18: =IF($F18<>"",IFERROR(_xlfn.XLOOKUP($F18,Taxa_från_edp!$B:$B,Taxa_från_edp!C:C),""),"") -> Tvåfackskärl 240L, rest/matavfall. Var 14:e dag | I18: =IF($F18<>"",IFERROR(_xlfn.XLOOKUP($F18,Taxa_från_edp!$B:$B,Taxa_från_edp!G:G),""),"") -> ÅRKV | J18: =IF($F18<>"",IFERROR(_xlfn.XLOOKUP($F18,Taxa_från_edp!$B:$B,Taxa_från_edp!K:K),""),"") -> 680 | M18: =IFERROR(IF(J18<>"",J18*1.25,IF(K18<>"",K18*1.25,"")),"") -> 850 | N18: =IFERROR(IF(J18<>"",L18*J18,IF(K18<>"",L18*K18,"")),"") -> 0
A19: §2.2.1 | B19: Hämtningsavgift per år för en- och tvåbostadshus | C19: Kärl 240 l (mat-/restavfall) | D19: Hämtning månadsvis | E19: st/år | F19: KÄ240RM12 | G19: =IF($F19<>"",$F19,IFERROR(_xlfn.XLOOKUP(ROW(),Taxa_Saknas!$H:$H,Taxa_Saknas!$G:$G),"")) -> KÄ240RM12 | H19: =IF($F19<>"",IFERROR(_xlfn.XLOOKUP($F19,Taxa_från_edp!$B:$B,Taxa_från_edp!C:C),""),"") | I19: =IF($F19<>"",IFERROR(_xlfn.XLOOKUP($F19,Taxa_från_edp!$B:$B,Taxa_från_edp!G:G),""),"") | J19: =IF($F19<>"",IFERROR(_xlfn.XLOOKUP($F19,Taxa_från_edp!$B:$B,Taxa_från_edp!K:K),""),"") | M19: =IFERROR(IF(J19<>"",J19*1.25,IF(K19<>"",K19*1.25,"")),"") | N19: =IFERROR(IF(J19<>"",L19*J19,IF(K19<>"",L19*K19,"")),"")
A20: §2.2.1 | B20: Hämtningsavgift per år för en- och tvåbostadshus | C20: Extrakärl 190 l (restavfall) | D20: Hämtning var 14:e dag | E20: st/år | F20: KÄ190XRM26 | G20: =IF($F20<>"",$F20,IFERROR(_xlfn.XLOOKUP(ROW(),Taxa_Saknas!$H:$H,Taxa_Saknas!$G:$G),"")) -> KÄ190XRM26 | H20: =IF($F20<>"",IFERROR(_xlfn.XLOOKUP($F20,Taxa_från_edp!$B:$B,Taxa_från_edp!C:C),""),"") -> Kärl 120-190L extrakärl, rest/matavfall. Var 14:e dag | I20: =IF($F20<>"",IFERROR(_xlfn.XLOOKUP($F20,Taxa_från_edp!$B:$B,Taxa_från_edp!G:G),""),"") -> ÅRKV | J20: =IF($F20<>"",IFERROR(_xlfn.XLOOKUP($F20,Taxa_från_edp!$B:$B,Taxa_från_edp!K:K),""),"") -> 680 | M20: =IFERROR(IF(J20<>"",J20*1.25,IF(K20<>"",K20*1.25,"")),"") -> 850 | N20: =IFERROR(IF(J20<>"",L20*J20,IF(K20<>"",L20*K20,"")),"") -> 0
A21: §2.2.1 | B21: Hämtningsavgift per år för en- och tvåbostadshus | C21: Extrakärl 190 l (restavfall) | D21: Hämtning månadsvis | E21: st/år | F21: KÄ190XRM12 | G21: =IF($F21<>"",$F21,IFERROR(_xlfn.XLOOKUP(ROW(),Taxa_Saknas!$H:$H,Taxa_Saknas!$G:$G),"")) -> KÄ190XRM12 | H21: =IF($F21<>"",IFERROR(_xlfn.XLOOKUP($F21,Taxa_från_edp!$B:$B,Taxa_från_edp!C:C),""),"") | I21: =IF($F21<>"",IFERROR(_xlfn.XLOOKUP($F21,Taxa_från_edp!$B:$B,Taxa_från_edp!G:G),""),"") | J21: =IF($F21<>"",IFERROR(_xlfn.XLOOKUP($F21,Taxa_från_edp!$B:$B,Taxa_från_edp!K:K),""),"") | M21: =IFERROR(IF(J21<>"",J21*1.25,IF(K21<>"",K21*1.25,"")),"") | N21: =IFERROR(IF(J21<>"",L21*J21,IF(K21<>"",L21*K21,"")),"")
A22: §2.2.1 | M22: =IFERROR(IF(J22<>"",J22*1.25,IF(K22<>"",K22*1.25,"")),"") | N22: =IFERROR(IF(J22<>"",L22*J22,IF(K22<>"",L22*K22,"")),"")
A23: §2.2.1 | G23: =IF($F23<>"",$F23,IFERROR(_xlfn.XLOOKUP(ROW(),Taxa_Saknas!$H:$H,Taxa_Saknas!$G:$G),"")) | H23: =IF($F23<>"",IFERROR(_xlfn.XLOOKUP($F23,Taxa_från_edp!$B:$B,Taxa_från_edp!C:C),""),"") | I23: =IF($F23<>"",IFERROR(_xlfn.XLOOKUP($F23,Taxa_från_edp!$B:$B,Taxa_från_edp!G:G),""),"") | J23: =IF($F23<>"",IFERROR(_xlfn.XLOOKUP($F23,Taxa_från_edp!$B:$B,Taxa_från_edp!K:K),""),"") | M23: =IFERROR(IF(J23<>"",J23*1.25,IF(K23<>"",K23*1.25,"")),"") | N23: =IFERROR(IF(J23<>"",L23*J23,IF(K23<>"",L23*K23,"")),"")
A24: §2.2.2 Hämtningsavgift per år för fritidshus | G24: =IF($F24<>"",$F24,IFERROR(_xlfn.XLOOKUP(ROW(),Taxa_Saknas!$H:$H,Taxa_Saknas!$G:$G),"")) | H24: =IF($F24<>"",IFERROR(_xlfn.XLOOKUP($F24,Taxa_från_edp!$B:$B,Taxa_från_edp!C:C),""),"") | I24: =IF($F24<>"",IFERROR(_xlfn.XLOOKUP($F24,Taxa_från_edp!$B:$B,Taxa_från_edp!G:G),""),"") | J24: =IF($F24<>"",IFERROR(_xlfn.XLOOKUP($F24,Taxa_från_edp!$B:$B,Taxa_från_edp!K:K),""),"") | M24: =IFERROR(IF(J24<>"",J24*1.25,IF(K24<>"",K24*1.25,"")),"") | N24: =IFERROR(IF(J24<>"",L24*J24,IF(K24<>"",L24*K24,"")),"")
A25: §2.2.2 | B25: Hämtningsavgift per år för fritidshus | C25: Kärl 240 l (mat-/restavfall) | D25: Hämtning var 14:e dag | E25: st/år | F25: KÄ240RM26FRI | G25: =IF($F25<>"",$F25,IFERROR(_xlfn.XLOOKUP(ROW(),Taxa_Saknas!$H:$H,Taxa_Saknas!$G:$G),"")) -> KÄ240RM26FRI | H25: =IF($F25<>"",IFERROR(_xlfn.XLOOKUP($F25,Taxa_från_edp!$B:$B,Taxa_från_edp!C:C),""),"") -> Tvåfackskärl 240L, rest/matavfall. Var 14:e dag fritidshus | I25: =IF($F25<>"",IFERROR(_xlfn.XLOOKUP($F25,Taxa_från_edp!$B:$B,Taxa_från_edp!G:G),""),"") -> ÅRKV | J25: =IF($F25<>"",IFERROR(_xlfn.XLOOKUP($F25,Taxa_från_edp!$B:$B,Taxa_från_edp!K:K),""),"") -> 680 | M25: =IFERROR(IF(J25<>"",J25*1.25,IF(K25<>"",K25*1.25,"")),"") -> 850 | N25: =IFERROR(IF(J25<>"",L25*J25,IF(K25<>"",L25*K25,"")),"") -> 0
A26: §2.2.2 | B26: Hämtningsavgift per år för fritidshus | C26: Kärl 240 l (mat-/restavfall) | D26: Hämtning månadsvis | E26: st/år | F26: KÄ240RM12FRI | G26: =IF($F26<>"",$F26,IFERROR(_xlfn.XLOOKUP(ROW(),Taxa_Saknas!$H:$H,Taxa_Saknas!$G:$G),"")) -> KÄ240RM12FRI | H26: =IF($F26<>"",IFERROR(_xlfn.XLOOKUP($F26,Taxa_från_edp!$B:$B,Taxa_från_edp!C:C),""),"") | I26: =IF($F26<>"",IFERROR(_xlfn.XLOOKUP($F26,Taxa_från_edp!$B:$B,Taxa_från_edp!G:G),""),"") | J26: =IF($F26<>"",IFERROR(_xlfn.XLOOKUP($F26,Taxa_från_edp!$B:$B,Taxa_från_edp!K:K),""),"") | M26: =IFERROR(IF(J26<>"",J26*1.25,IF(K26<>"",K26*1.25,"")),"") | N26: =IFERROR(IF(J26<>"",L26*J26,IF(K26<>"",L26*K26,"")),"")
A27: §2.2.2 | B27: Hämtningsavgift per år för fritidshus | C27: Extrakärl 190 l (restavfall) | D27: Hämtning var 14:e dag | E27: st/år | F27: KÄ190XRM26FRI | G27: =IF($F27<>"",$F27,IFERROR(_xlfn.XLOOKUP(ROW(),Taxa_Saknas!$H:$H,Taxa_Saknas!$G:$G),"")) -> KÄ190XRM26FRI | H27: =IF($F27<>"",IFERROR(_xlfn.XLOOKUP($F27,Taxa_från_edp!$B:$B,Taxa_från_edp!C:C),""),"") | I27: =IF($F27<>"",IFERROR(_xlfn.XLOOKUP($F27,Taxa_från_edp!$B:$B,Taxa_från_edp!G:G),""),"") | J27: =IF($F27<>"",IFERROR(_xlfn.XLOOKUP($F27,Taxa_från_edp!$B:$B,Taxa_från_edp!K:K),""),"") | M27: =IFERROR(IF(J27<>"",J27*1.25,IF(K27<>"",K27*1.25,"")),"") | N27: =IFERROR(IF(J27<>"",L27*J27,IF(K27<>"",L27*K27,"")),"")
A28: §2.2.2 | M28: =IFERROR(IF(J28<>"",J28*1.25,IF(K28<>"",K28*1.25,"")),"") | N28: =IFERROR(IF(J28<>"",L28*J28,IF(K28<>"",L28*K28,"")),"")
A29: §2.2.2 | B29: Hämtningsavgift per år för fritidshus | C29: Kärl 370 l (papper-/plastförpackningar) | D29: Kostnadsfritt | E29: st/år | F29: KÄ370FP | G29: =IF($F29<>"",$F29,IFERROR(_xlfn.XLOOKUP(ROW(),Taxa_Saknas!$H:$H,Taxa_Saknas!$G:$G),"")) -> KÄ370FP | H29: =IF($F29<>"",IFERROR(_xlfn.XLOOKUP($F29,Taxa_från_edp!$B:$B,Taxa_från_edp!C:C),""),"") | I29: =IF($F29<>"",IFERROR(_xlfn.XLOOKUP($F29,Taxa_från_edp!$B:$B,Taxa_från_edp!G:G),""),"") | J29: =IF($F29<>"",IFERROR(_xlfn.XLOOKUP($F29,Taxa_från_edp!$B:$B,Taxa_från_edp!K:K),""),"") | M29: =IFERROR(IF(J29<>"",J29*1.25,IF(K29<>"",K29*1.25,"")),"") | N29: =IFERROR(IF(J29<>"",L29*J29,IF(K29<>"",L29*K29,"")),"")
A30: §2.2.2 | G30: =IF($F30<>"",$F30,IFERROR(_xlfn.XLOOKUP(ROW(),Taxa_Saknas!$H:$H,Taxa_Saknas!$G:$G),"")) | H30: =IF($F30<>"",IFERROR(_xlfn.XLOOKUP($F30,Taxa_från_edp!$B:$B,Taxa_från_edp!C:C),""),"") | I30: =IF($F30<>"",IFERROR(_xlfn.XLOOKUP($F30,Taxa_från_edp!$B:$B,Taxa_från_edp!G:G),""),"") | J30: =IF($F30<>"",IFERROR(_xlfn.XLOOKUP($F30,Taxa_från_edp!$B:$B,Taxa_från_edp!K:K),""),"") | M30: =IFERROR(IF(J30<>"",J30*1.25,IF(K30<>"",K30*1.25,"")),"") | N30: =IFERROR(IF(J30<>"",L30*J30,IF(K30<>"",L30*K30,"")),"")
A31: §2.2.3 Gemensam uppsamlingsplats inom hämtningsområde X | G31: =IF($F31<>"",$F31,IFERROR(_xlfn.XLOOKUP(ROW(),Taxa_Saknas!$H:$H,Taxa_Saknas!$G:$G),"")) | H31: =IF($F31<>"",IFERROR(_xlfn.XLOOKUP($F31,Taxa_från_edp!$B:$B,Taxa_från_edp!C:C),""),"") | I31: =IF($F31<>"",IFERROR(_xlfn.XLOOKUP($F31,Taxa_från_edp!$B:$B,Taxa_från_edp!G:G),""),"") | J31: =IF($F31<>"",IFERROR(_xlfn.XLOOKUP($F31,Taxa_från_edp!$B:$B,Taxa_från_edp!K:K),""),"") | M31: =IFERROR(IF(J31<>"",J31*1.25,IF(K31<>"",K31*1.25,"")),"") | N31: =IFERROR(IF(J31<>"",L31*J31,IF(K31<>"",L31*K31,"")),"")
A32: §2.2.3 | B32: Gemensam uppsamlingsplats inom hämtningsområde X | C32: Gemensam uppsamlingsplats för mat-/restavfall | E32: st/år | F32: GEMUPPFRI | G32: =IF($F32<>"",$F32,IFERROR(_xlfn.XLOOKUP(ROW(),Taxa_Saknas!$H:$H,Taxa_Saknas!$G:$G),"")) -> GEMUPPFRI | H32: =IF($F32<>"",IFERROR(_xlfn.XLOOKUP($F32,Taxa_från_edp!$B:$B,Taxa_från_edp!C:C),""),"") -> Gemensam uppsamlingsplats, fritidshus | I32: =IF($F32<>"",IFERROR(_xlfn.XLOOKUP($F32,Taxa_från_edp!$B:$B,Taxa_från_edp!G:G),""),"") -> ÅRKV | J32: =IF($F32<>"",IFERROR(_xlfn.XLOOKUP($F32,Taxa_från_edp!$B:$B,Taxa_från_edp!K:K),""),"") -> 600 | M32: =IFERROR(IF(J32<>"",J32*1.25,IF(K32<>"",K32*1.25,"")),"") -> 750 | N32: =IFERROR(IF(J32<>"",L32*J32,IF(K32<>"",L32*K32,"")),"") -> 0
A33: §2.2.3 | B33: Gemensam uppsamlingsplats inom hämtningsområde X | C33: Gemensam uppsamlingsplats för förpackningar | D33: Kostnadsfritt | E33: st/år | F33: GEMUPPFRI | G33: =IF($F33<>"",$F33,IFERROR(_xlfn.XLOOKUP(ROW(),Taxa_Saknas!$H:$H,Taxa_Saknas!$G:$G),"")) -> GEMUPPFRI | H33: =IF($F33<>"",IFERROR(_xlfn.XLOOKUP($F33,Taxa_från_edp!$B:$B,Taxa_från_edp!C:C),""),"") -> Gemensam uppsamlingsplats, fritidshus | I33: =IF($F33<>"",IFERROR(_xlfn.XLOOKUP($F33,Taxa_från_edp!$B:$B,Taxa_från_edp!G:G),""),"") -> ÅRKV | J33: =IF($F33<>"",IFERROR(_xlfn.XLOOKUP($F33,Taxa_från_edp!$B:$B,Taxa_från_edp!K:K),""),"") -> 600 | M33: =IFERROR(IF(J33<>"",J33*1.25,IF(K33<>"",K33*1.25,"")),"") -> 750 | N33: =IFERROR(IF(J33<>"",L33*J33,IF(K33<>"",L33*K33,"")),"") -> 0
A34: §2.2.3 | B34: Gemensam uppsamlingsplats inom hämtningsområde X | C34: Extra digital licens (årskostnad) | E34: st/år | F34: GEMUPPEXTRAFRI | G34: =IF($F34<>"",$F34,IFERROR(_xlfn.XLOOKUP(ROW(),Taxa_Saknas!$H:$H,Taxa_Saknas!$G:$G),"")) -> GEMUPPEXTRAFRI | H34: =IF($F34<>"",IFERROR(_xlfn.XLOOKUP($F34,Taxa_från_edp!$B:$B,Taxa_från_edp!C:C),""),"") -> Extra mobilnyckel till Gemensam uppsamlingsplats, fritidshus | I34: =IF($F34<>"",IFERROR(_xlfn.XLOOKUP($F34,Taxa_från_edp!$B:$B,Taxa_från_edp!G:G),""),"") -> ÅRPR | J34: =IF($F34<>"",IFERROR(_xlfn.XLOOKUP($F34,Taxa_från_edp!$B:$B,Taxa_från_edp!K:K),""),"") -> 80 | M34: =IFERROR(IF(J34<>"",J34*1.25,IF(K34<>"",K34*1.25,"")),"") -> 100 | N34: =IFERROR(IF(J34<>"",L34*J34,IF(K34<>"",L34*K34,"")),"") -> 0
A35: §2.2.3 | B35: Gemensam uppsamlingsplats inom hämtningsområde X | C35: Fysisk nyckel, kallad fob (engångskostnad) | E35: st/tillfälle | F35: FOBFRI | G35: =IF($F35<>"",$F35,IFERROR(_xlfn.XLOOKUP(ROW(),Taxa_Saknas!$H:$H,Taxa_Saknas!$G:$G),"")) -> FOBFRI | H35: =IF($F35<>"",IFERROR(_xlfn.XLOOKUP($F35,Taxa_från_edp!$B:$B,Taxa_från_edp!C:C),""),"") -> Nyckelfob mat- och restavfall fritidshus (engångs) | I35: =IF($F35<>"",IFERROR(_xlfn.XLOOKUP($F35,Taxa_från_edp!$B:$B,Taxa_från_edp!G:G),""),"") -> KVAN | J35: =IF($F35<>"",IFERROR(_xlfn.XLOOKUP($F35,Taxa_från_edp!$B:$B,Taxa_från_edp!K:K),""),"") -> 1200 | M35: =IFERROR(IF(J35<>"",J35*1.25,IF(K35<>"",K35*1.25,"")),"") -> 1500 | N35: =IFERROR(IF(J35<>"",L35*J35,IF(K35<>"",L35*K35,"")),"") -> 0
A36: §2.2.3 | B36: Gemensam uppsamlingsplats inom hämtningsområde X | C36: Byte av telefonnummer kopplat till licens | E36: st/tillfälle | F36: GEMUPPBYTE | G36: =IF($F36<>"",$F36,IFERROR(_xlfn.XLOOKUP(ROW(),Taxa_Saknas!$H:$H,Taxa_Saknas!$G:$G),"")) -> GEMUPPBYTE | H36: =IF($F36<>"",IFERROR(_xlfn.XLOOKUP($F36,Taxa_från_edp!$B:$B,Taxa_från_edp!C:C),""),"") | I36: =IF($F36<>"",IFERROR(_xlfn.XLOOKUP($F36,Taxa_från_edp!$B:$B,Taxa_från_edp!G:G),""),"") | J36: =IF($F36<>"",IFERROR(_xlfn.XLOOKUP($F36,Taxa_från_edp!$B:$B,Taxa_från_edp!K:K),""),"") | M36: =IFERROR(IF(J36<>"",J36*1.25,IF(K36<>"",K36*1.25,"")),"") | N36: =IFERROR(IF(J36<>"",L36*J36,IF(K36<>"",L36*K36,"")),"")
A37: §2.2.3 | B37: Gemensam uppsamlingsplats inom hämtningsområde X | C37: Kostnad för öppning av behållare | E37: st/tillfälle | F37: GEMUPPÖPP | G37: =IF($F37<>"",$F37,IFERROR(_xlfn.XLOOKUP(ROW(),Taxa_Saknas!$H:$H,Taxa_Saknas!$G:$G),"")) -> GEMUPPÖPP | H37: =IF($F37<>"",IFERROR(_xlfn.XLOOKUP($F37,Taxa_från_edp!$B:$B,Taxa_från_edp!C:C),""),"") | I37: =IF($F37<>"",IFERROR(_xlfn.XLOOKUP($F37,Taxa_från_edp!$B:$B,Taxa_från_edp!G:G),""),"") | J37: =IF($F37<>"",IFERROR(_xlfn.XLOOKUP($F37,Taxa_från_edp!$B:$B,Taxa_från_edp!K:K),""),"") | M37: =IFERROR(IF(J37<>"",J37*1.25,IF(K37<>"",K37*1.25,"")),"") | N37: =IFERROR(IF(J37<>"",L37*J37,IF(K37<>"",L37*K37,"")),"")
A38: §2.2.3 | G38: =IF($F38<>"",$F38,IFERROR(_xlfn.XLOOKUP(ROW(),Taxa_Saknas!$H:$H,Taxa_Saknas!$G:$G),"")) | H38: =IF($F38<>"",IFERROR(_xlfn.XLOOKUP($F38,Taxa_från_edp!$B:$B,Taxa_från_edp!C:C),""),"") | I38: =IF($F38<>"",IFERROR(_xlfn.XLOOKUP($F38,Taxa_från_edp!$B:$B,Taxa_från_edp!G:G),""),"") | J38: =IF($F38<>"",IFERROR(_xlfn.XLOOKUP($F38,Taxa_från_edp!$B:$B,Taxa_från_edp!K:K),""),"") | M38: =IFERROR(IF(J38<>"",J38*1.25,IF(K38<>"",K38*1.25,"")),"") | N38: =IFERROR(IF(J38<>"",L38*J38,IF(K38<>"",L38*K38,"")),"")
A39: §2.2.4 Hämtningsavgift per år för flerbostadshus | G39: =IF($F39<>"",$F39,IFERROR(_xlfn.XLOOKUP(ROW(),Taxa_Saknas!$H:$H,Taxa_Saknas!$G:$G),"")) | H39: =IF($F39<>"",IFERROR(_xlfn.XLOOKUP($F39,Taxa_från_edp!$B:$B,Taxa_från_edp!C:C),""),"") | I39: =IF($F39<>"",IFERROR(_xlfn.XLOOKUP($F39,Taxa_från_edp!$B:$B,Taxa_från_edp!G:G),""),"") | J39: =IF($F39<>"",IFERROR(_xlfn.XLOOKUP($F39,Taxa_från_edp!$B:$B,Taxa_från_edp!K:K),""),"") | M39: =IFERROR(IF(J39<>"",J39*1.25,IF(K39<>"",K39*1.25,"")),"") | N39: =IFERROR(IF(J39<>"",L39*J39,IF(K39<>"",L39*K39,"")),"")
A40: §2.2.4 | B40: Hämtningsavgift per år för flerbostadshus | C40: Kärl 240 l (mat-/restavfall) | D40: Hämtning varje vecka | E40: st/år | F40: KÄ240RM52FV | G40: =IF($F40<>"",$F40,IFERROR(_xlfn.XLOOKUP(ROW(),Taxa_Saknas!$H:$H,Taxa_Saknas!$G:$G),"")) -> KÄ240RM52FV | H40: =IF($F40<>"",IFERROR(_xlfn.XLOOKUP($F40,Taxa_från_edp!$B:$B,Taxa_från_edp!C:C),""),"") -> Tvåfackskärl 240L, rest/matavfall. Varje vecka. FLB/VHT | I40: =IF($F40<>"",IFERROR(_xlfn.XLOOKUP($F40,Taxa_från_edp!$B:$B,Taxa_från_edp!G:G),""),"") -> ÅRKV | J40: =IF($F40<>"",IFERROR(_xlfn.XLOOKUP($F40,Taxa_från_edp!$B:$B,Taxa_från_edp!K:K),""),"") -> 1000 | M40: =IFERROR(IF(J40<>"",J40*1.25,IF(K40<>"",K40*1.25,"")),"") -> 1250 | N40: =IFERROR(IF(J40<>"",L40*J40,IF(K40<>"",L40*K40,"")),"") -> 0
A41: §2.2.4 | B41: Hämtningsavgift per år för flerbostadshus | C41: Kärl 240 l (mat-/restavfall) | D41: Hämtning var 14:e dag | E41: st/år | F41: KÄ240RM26FV | G41: =IF($F41<>"",$F41,IFERROR(_xlfn.XLOOKUP(ROW(),Taxa_Saknas!$H:$H,Taxa_Saknas!$G:$G),"")) -> KÄ240RM26FV | H41: =IF($F41<>"",IFERROR(_xlfn.XLOOKUP($F41,Taxa_från_edp!$B:$B,Taxa_från_edp!C:C),""),"") -> Tvåfackskärl 240L, rest/matavfall. Var 14:e dag. FLB/VHT | I41: =IF($F41<>"",IFERROR(_xlfn.XLOOKUP($F41,Taxa_från_edp!$B:$B,Taxa_från_edp!G:G),""),"") -> ÅRKV | J41: =IF($F41<>"",IFERROR(_xlfn.XLOOKUP($F41,Taxa_från_edp!$B:$B,Taxa_från_edp!K:K),""),"") -> 680 | M41: =IFERROR(IF(J41<>"",J41*1.25,IF(K41<>"",K41*1.25,"")),"") -> 850 | N41: =IFERROR(IF(J41<>"",L41*J41,IF(K41<>"",L41*K41,"")),"") -> 0
A42: §2.2.4 | B42: Hämtningsavgift per år för flerbostadshus | C42: Kärl 240 l (mat-/restavfall) | D42: Hämtning månadsvis | E42: st/år | F42: KÄ240RM12FV | G42: =IF($F42<>"",$F42,IFERROR(_xlfn.XLOOKUP(ROW(),Taxa_Saknas!$H:$H,Taxa_Saknas!$G:$G),"")) -> KÄ240RM12FV | H42: =IF($F42<>"",IFERROR(_xlfn.XLOOKUP($F42,Taxa_från_edp!$B:$B,Taxa_från_edp!C:C),""),"") | I42: =IF($F42<>"",IFERROR(_xlfn.XLOOKUP($F42,Taxa_från_edp!$B:$B,Taxa_från_edp!G:G),""),"") | J42: =IF($F42<>"",IFERROR(_xlfn.XLOOKUP($F42,Taxa_från_edp!$B:$B,Taxa_från_edp!K:K),""),"") | M42: =IFERROR(IF(J42<>"",J42*1.25,IF(K42<>"",K42*1.25,"")),"") | N42: =IFERROR(IF(J42<>"",L42*J42,IF(K42<>"",L42*K42,"")),"")
...

Sheet Taxepunkter_Rådata
A1: Paragraf | B1: Paragrafnamn | C1: Taxapunkt | D1: Variant | E1: Enhet | F1: Taxakod | G1: Taxabeskrivning | H1: Faktor | I1: Aktuellt pris (exkl m) | J1: Antal | K1: Pris (kr) | L1: Intäkt (kr)
A2: =Taxepunkter!A7 -> §2.1 | B2: =Taxepunkter!B7 -> Grundavgift | C2: =Taxepunkter!C7 -> En- och tvåbostadshus | D2: =Taxepunkter!D7 -> 0 | E2: =Taxepunkter!E7 -> st/år | F2: =Taxepunkter!F7 -> GRUNDSMÅ | G2: =Taxepunkter!G7 -> GRUNDSMÅ | H2: =Taxepunkter!H7 -> Grundavgift, småhus 1- och 2 familjshus | ... L2: =Taxepunkter!L7 -> 0
A3: =Taxepunkter!A8 -> §2.1 | B3: =Taxepunkter!B8 -> Grundavgift | C3: =Taxepunkter!C8 -> Fritidshus | D3: =Taxepunkter!D8 -> 0 | E3: =Taxepunkter!E8 -> st/år | F3: =Taxepunkter!F8 -> GRUNDFRI | G3: =Taxepunkter!G8 -> GRUNDFRI | H3: =Taxepunkter!H8 -> Grundavgift, fritidshus | ... L3: =Taxepunkter!L8 -> 0
A4: =Taxepunkter!A9 -> §2.1 | B4: =Taxepunkter!B9 -> Grundavgift | C4: =Taxepunkter!C9 -> Verksamhet | D4: =Taxepunkter!D9 -> 0 | E4: =Taxepunkter!E9 -> st/år | F4: =Taxepunkter!F9 -> GRUNDVHT | G4: =Taxepunkter!G9 -> GRUNDVHT | H4: =Taxepunkter!H9 -> Grundavgift, verksamheter | ... L4: =Taxepunkter!L9 -> 0
A5: =Taxepunkter!A10 -> §2.1 | B5: =Taxepunkter!B10 -> Grundavgift | C5: =Taxepunkter!C10 -> Lägenhet i flerbostadshus | D5: =Taxepunkter!D10 -> 0 | E5: =Taxepunkter!E10 -> st/år | F5: =Taxepunkter!F10 -> GRUNDFLB | G5: =Taxepunkter!G10 -> GRUNDFLB | H5: =Taxepunkter!H10 -> Grundavgift, del i flerbostadshus | ... L5: =Taxepunkter!L10 -> 0
A6: =Taxepunkter!A11 -> §2.1 | B6: =Taxepunkter!B11 -> Grundavgift | C6: =Taxepunkter!C11 -> Lägenhet för specialändamål | D6: =Taxepunkter!D11 -> 0 | E6: =Taxepunkter!E11 -> st/år | F6: =Taxepunkter!F11 -> GRUNDSPEC | G6: =Taxepunkter!G11 -> GRUNDSPEC | H6: =Taxepunkter!H11 | ... L6: =Taxepunkter!L11 -> 0
A7: =Taxepunkter!A12 -> §2.1 | B7: =Taxepunkter!B12 -> Grundavgift | C7: =Taxepunkter!C12 -> Anläggning | D7: =Taxepunkter!D12 -> 0 | E7: =Taxepunkter!E12 -> st/år | F7: =Taxepunkter!F12 -> GRUNDANL | G7: =Taxepunkter!G12 -> GRUNDANL | H7: =Taxepunkter!H12 | ... L7: =Taxepunkter!L12 -> 0
A8: =Taxepunkter!A13 -> §2.1 | B8: =Taxepunkter!B13 -> Grundavgift | C8: =Taxepunkter!C13 -> Säsongsbaserad uppställningsplats | D8: =Taxepunkter!D13 -> 0 | E8: =Taxepunkter!E13 -> st/år | F8: =Taxepunkter!F13 -> GRUNDSÄS | G8: =Taxepunkter!G13 -> GRUNDSÄS | H8: =Taxepunkter!H13 | ... L8: =Taxepunkter!L13 -> 0
A9: =Taxepunkter!A14 -> §2.1 | B9: =Taxepunkter!B14 -> Grundavgift | C9: =Taxepunkter!C14 -> Campingstuga/-lägenhet | D9: =Taxepunkter!D14 -> 0 | E9: =Taxepunkter!E14 -> st/år | F9: =Taxepunkter!F14 -> GRUNDCAMP | G9: =Taxepunkter!G14 -> GRUNDCAMP | H9: =Taxepunkter!H14 | ... L9: =Taxepunkter!L14 -> 0
A10: =Taxepunkter!A15 -> §2.1 | B10: =Taxepunkter!B15 -> Grundavgift | C10: =Taxepunkter!C15 -> Administrativ avgift vid beviljad dispens om uppehåll i hämtning eller eget omhändertagande av avfall under kommunalt ansvar | D10: =Taxepunkter!D15 -> 0 | E10: =Taxepunkter!E15 -> st/år | F10: =Taxepunkter!F15 -> ADMINDISP | G10: =Taxepunkter!G15 -> ADMINDISP | H10: =Taxepunkter!H15 | ... L10: =Taxepunkter!L15 -> 0
A11: =Taxepunkter!A17 -> §2.2.1 Hämtningsavgift per år för en- och tvåbostadshus | B11: =Taxepunkter!B17 -> 0 | C11: =Taxepunkter!C17 -> 0 | D11: =Taxepunkter!D17 -> 0 | E11: =Taxepunkter!E17 -> 0 | F11: =Taxepunkter!F17 -> 0 | G11: =Taxepunkter!G17 | H11: =Taxepunkter!H17 | ... L11: =Taxepunkter!L17 -> 0
A12: =Taxepunkter!A18 -> §2.2.1 | B12: =Taxepunkter!B18 -> Hämtningsavgift per år för en- och tvåbostadshus | C12: =Taxepunkter!C18 -> Kärl 240 l (mat-/restavfall) | D12: =Taxepunkter!D18 -> Hämtning var 14:e dag | E12: =Taxepunkter!E18 -> st/år | F12: =Taxepunkter!F18 -> KÄ240RM26 | G12: =Taxepunkter!G18 -> KÄ240RM26 | H12: =Taxepunkter!H18 -> Tvåfackskärl 240L, rest/matavfall. Var 14:e dag | ... L12: =Taxepunkter!L18 -> 0
A13: =Taxepunkter!A20 -> §2.2.1 | B13: =Taxepunkter!B20 -> Hämtningsavgift per år för en- och tvåbostadshus | C13: =Taxepunkter!C20 -> Extrakärl 190 l (restavfall) | D13: =Taxepunkter!D20 -> Hämtning var 14:e dag | E13: =Taxepunkter!E20 -> st/år | F13: =Taxepunkter!F20 -> KÄ190XRM26 | G13: =Taxepunkter!G20 -> KÄ190XRM26 | H13: =Taxepunkter!H20 -> Kärl 120-190L extrakärl, rest/matavfall. Var 14:e dag | ... L13: =Taxepunkter!L20 -> 0
A14: =Taxepunkter!A21 -> §2.2.1 | B14: =Taxepunkter!B21 -> Hämtningsavgift per år för en- och tvåbostadshus | C14: =Taxepunkter!C21 -> Extrakärl 190 l (restavfall) | D14: =Taxepunkter!D21 -> Hämtning månadsvis | E14: =Taxepunkter!E21 -> st/år | F14: =Taxepunkter!F21 -> KÄ190XRM12 | G14: =Taxepunkter!G21 -> KÄ190XRM12 | H14: =Taxepunkter!H21 | ... L14: =Taxepunkter!L21 -> 0
A15: =Taxepunkter!A23 -> §2.2.1 | B15: =Taxepunkter!B23 -> 0 | C15: =Taxepunkter!C23 -> 0 | D15: =Taxepunkter!D23 -> 0 | E15: =Taxepunkter!E23 -> 0 | F15: =Taxepunkter!F23 -> 0 | G15: =Taxepunkter!G23 | H15: =Taxepunkter!H23 | ... L15: =Taxepunkter!L23 -> 0
A16: =Taxepunkter!A24 -> §2.2.2 Hämtningsavgift per år för fritidshus | B16: =Taxepunkter!B24 -> 0 | C16: =Taxepunkter!C24 -> 0 | D16: =Taxepunkter!D24 -> 0 | E16: =Taxepunkter!E24 -> 0 | F16: =Taxepunkter!F24 -> 0 | G16: =Taxepunkter!G24 | H16: =Taxepunkter!H24 | ... L16: =Taxepunkter!L24 -> 0
A17: =Taxepunkter!A25 -> §2.2.2 | B17: =Taxepunkter!B25 -> Hämtningsavgift per år för fritidshus | C17: =Taxepunkter!C25 -> Kärl 240 l (mat-/restavfall) | D17: =Taxepunkter!D25 -> Hämtning var 14:e dag | E17: =Taxepunkter!E25 -> st/år | F17: =Taxepunkter!F25 -> KÄ240RM26FRI | G17: =Taxepunkter!G25 -> KÄ240RM26FRI | H17: =Taxepunkter!H25 -> Tvåfackskärl 240L, rest/matavfall. Var 14:e dag fritidshus | ... L17: =Taxepunkter!L25 -> 0
A18: =Taxepunkter!A26 -> §2.2.2 | B18: =Taxepunkter!B26 -> Hämtningsavgift per år för fritidshus | C18: =Taxepunkter!C26 -> Kärl 240 l (mat-/restavfall) | D18: =Taxepunkter!D26 -> Hämtning månadsvis | E18: =Taxepunkter!E26 -> st/år | F18: =Taxepunkter!F26 -> KÄ240RM12FRI | G18: =Taxepunkter!G26 -> KÄ240RM12FRI | H18: =Taxepunkter!H26 | ... L18: =Taxepunkter!L26 -> 0
A19: =Taxepunkter!A27 -> §2.2.2 | B19: =Taxepunkter!B27 -> Hämtningsavgift per år för fritidshus | C19: =Taxepunkter!C27 -> Extrakärl 190 l (restavfall) | D19: =Taxepunkter!D27 -> Hämtning var 14:e dag | E19: =Taxepunkter!E27 -> st/år | F19: =Taxepunkter!F27 -> KÄ190XRM26FRI | G19: =Taxepunkter!G27 -> KÄ190XRM26FRI | H19: =Taxepunkter!H27 | ... L19: =Taxepunkter!L27 -> 0
A20: =Taxepunkter!A29 -> §2.2.2 | B20: =Taxepunkter!B29 -> Hämtningsavgift per år för fritidshus | C20: =Taxepunkter!C29 -> Kärl 370 l (papper-/plastförpackningar) | D20: =Taxepunkter!D29 -> Kostnadsfritt | E20: =Taxepunkter!E29 -> st/år | F20: =Taxepunkter!F29 -> KÄ370FP | G20: =Taxepunkter!G29 -> KÄ370FP | H20: =Taxepunkter!H29 | ... L20: =Taxepunkter!L29 -> 0
A21: =Taxepunkter!A30 -> §2.2.2 | B21: =Taxepunkter!B30 -> 0 | C21: =Taxepunkter!C30 -> 0 | D21: =Taxepunkter!D30 -> 0 | E21: =Taxepunkter!E30 -> 0 | F21: =Taxepunkter!F30 -> 0 | G21: =Taxepunkter!G30 | H21: =Taxepunkter!H30 | ... L21: =Taxepunkter!L30 -> 0
A22: =Taxepunkter!A31 -> §2.2.3 Gemensam uppsamlingsplats inom hämtningsområde X | B22: =Taxepunkter!B31 -> 0 | C22: =Taxepunkter!C31 -> 0 | D22: =Taxepunkter!D31 -> 0 | E22: =Taxepunkter!E31 -> 0 | F22: =Taxepunkter!F31 -> 0 | G22: =Taxepunkter!G31 | H22: =Taxepunkter!H31 | ... L22: =Taxepunkter!L31 -> 0
A23: =Taxepunkter!A32 -> §2.2.3 | B23: =Taxepunkter!B32 -> Gemensam uppsamlingsplats inom hämtningsområde X | C23: =Taxepunkter!C32 -> Gemensam uppsamlingsplats för mat-/restavfall | D23: =Taxepunkter!D32 -> 0 | E23: =Taxepunkter!E32 -> st/år | F23: =Taxepunkter!F32 -> GEMUPPFRI | G23: =Taxepunkter!G32 -> GEMUPPFRI | H23: =Taxepunkter!H32 -> Gemensam uppsamlingsplats, fritidshus | ... L23: =Taxepunkter!L32 -> 0
A24: =Taxepunkter!A33 -> §2.2.3 | B24: =Taxepunkter!B33 -> Gemensam uppsamlingsplats inom hämtningsområde X | C24: =Taxepunkter!C33 -> Gemensam uppsamlingsplats för förpackningar | D24: =Taxepunkter!D33 -> Kostnadsfritt | E24: =Taxepunkter!E33 -> st/år | F24: =Taxepunkter!F33 -> GEMUPPFRI | G24: =Taxepunkter!G33 -> GEMUPPFRI | H24: =Taxepunkter!H33 -> Gemensam uppsamlingsplats, fritidshus | ... L24: =Taxepunkter!L33 -> 0
A25: =Taxepunkter!A34 -> §2.2.3 | B25: =Taxepunkter!B34 -> Gemensam uppsamlingsplats inom hämtningsområde X | C25: =Taxepunkter!C34 -> Extra digital licens (årskostnad) | D25: =Taxepunkter!D34 -> 0 | E25: =Taxepunkter!E34 -> st/år | F25: =Taxepunkter!F34 -> GEMUPPEXTRAFRI | G25: =Taxepunkter!G34 -> GEMUPPEXTRAFRI | H25: =Taxepunkter!H34 -> Extra mobilnyckel till Gemensam uppsamlingsplats, fritidshus | ... L25: =Taxepunkter!L34 -> 0
A26: =Taxepunkter!A35 -> §2.2.3 | B26: =Taxepunkter!B35 -> Gemensam uppsamlingsplats inom hämtningsområde X | C26: =Taxepunkter!C35 -> Fysisk nyckel, kallad fob (engångskostnad) | D26: =Taxepunkter!D35 -> 0 | E26: =Taxepunkter!E35 -> st/tillfälle | F26: =Taxepunkter!F35 -> FOBFRI | G26: =Taxepunkter!G35 -> FOBFRI | H26: =Taxepunkter!H35 -> Nyckelfob mat- och restavfall fritidshus (engångs) | ... L26: =Taxepunkter!L35 -> 0
A27: =Taxepunkter!A36 -> §2.2.3 | B27: =Taxepunkter!B36 -> Gemensam uppsamlingsplats inom hämtningsområde X | C27: =Taxepunkter!C36 -> Byte av telefonnummer kopplat till licens | D27: =Taxepunkter!D36 -> 0 | E27: =Taxepunkter!E36 -> st/tillfälle | F27: =Taxepunkter!F36 -> GEMUPPBYTE | G27: =Taxepunkter!G36 -> GEMUPPBYTE | H27: =Taxepunkter!H36 | ... L27: =Taxepunkter!L36 -> 0
A28: =Taxepunkter!A37 -> §2.2.3 | B28: =Taxepunkter!B37 -> Gemensam uppsamlingsplats inom hämtningsområde X | C28: =Taxepunkter!C37 -> Kostnad för öppning av behållare | D28: =Taxepunkter!D37 -> 0 | E28: =Taxepunkter!E37 -> st/tillfälle | F28: =Taxepunkter!F37 -> GEMUPPÖPP | G28: =Taxepunkter!G37 -> GEMUPPÖPP | H28: =Taxepunkter!H37 | ... L28: =Taxepunkter!L37 -> 0
A29: =Taxepunkter!A38 -> §2.2.3 | B29: =Taxepunkter!B38 -> 0 | C29: =Taxepunkter!C38 -> 0 | D29: =Taxepunkter!D38 -> 0 | E29: =Taxepunkter!E38 -> 0 | F29: =Taxepunkter!F38 -> 0 | G29: =Taxepunkter!G38 | H29: =Taxepunkter!H38 | ... L29: =Taxepunkter!L38 -> 0
A30: =Taxepunkter!A39 -> §2.2.4 Hämtningsavgift per år för flerbostadshus | B30: =Taxepunkter!B39 -> 0 | C30: =Taxepunkter!C39 -> 0 | D30: =Taxepunkter!D39 -> 0 | E30: =Taxepunkter!E39 -> 0 | F30: =Taxepunkter!F39 -> 0 | G30: =Taxepunkter!G39 | H30: =Taxepunkter!H39 | ... L30: =Taxepunkter!L39 -> 0
A31: =Taxepunkter!A40 -> §2.2.4 | B31: =Taxepunkter!B40 -> Hämtningsavgift per år för flerbostadshus | C31: =Taxepunkter!C40 -> Kärl 240 l (mat-/restavfall) | D31: =Taxepunkter!D40 -> Hämtning varje vecka | E31: =Taxepunkter!E40 -> st/år | F31: =Taxepunkter!F40 -> KÄ240RM52FV | G31: =Taxepunkter!G40 -> KÄ240RM52FV | H31: =Taxepunkter!H40 -> Tvåfackskärl 240L, rest/matavfall. Varje vecka. FLB/VHT | ... L31: =Taxepunkter!L40 -> 0
... A48: =Taxepunkter!A57 -> §2.2.4 | B48: =Taxepunkter!B57 -> Hämtningsavgift per år för flerbostadshus | C48: =Taxepunkter!C57 -> Kärl 370 l (förpackningar) | D48: =Taxepunkter!D57 -> Hämtning månadsvis | E48: =Taxepunkter!E57 -> st/år | F48: =Taxepunkter!F57 -> KÄ370FP12FV | G48: =Taxepunkter!G57 -> KÄ370FP12FV | H48: =Taxepunkter!H57 | ... L48: =Taxepunkter!L57 -> 0
A49: =Taxepunkter!A59 -> §2.2.4 | B49: =Taxepunkter!B59 -> Hämtningsavgift per år för flerbostadshus | C49: =Taxepunkter!C59 -> Kärl 660 l (förpackningar) | D49: =Taxepunkter!D59 -> Hämtning var 14:e dag | E49: =Taxepunkter!E59 -> st/år | F49: =Taxepunkter!F59 -> KÄ660FP26FV | G49: =Taxepunkter!G59 -> KÄ660FP26FV | H49: =Taxepunkter!H59 | ... L49: =Taxepunkter!L59 -> 0
A50: =Taxepunkter!A60 -> §2.2.4 | B50: =Taxepunkter!B60 -> Hämtningsavgift per år för flerbostadshus | C50: =Taxepunkter!C60 -> Kärl 660 l (förpackningar) | D50: =Taxepunkter!D60 -> Hämtning månadsvis | E50: =Taxepunkter!E60 -> st/år | F50: =Taxepunkter!F60 -> KÄ660FP12FV | G50: =Taxepunkter!G60 -> KÄ660FP12FV | H50: =Taxepunkter!H60 | ... L50: =Taxepunkter!L60 -> 0
A51: =Taxepunkter!A61 -> §2.2.4 | B51: =Taxepunkter!B61 -> Hämtningsavgift per år för flerbostadshus | C51: =Taxepunkter!C61 -> Kärl 190 l (tidningar och returpapper) | D51: =Taxepunkter!D61 -> Hämtning varje vecka | E51: =Taxepunkter!E61 -> st/år | F51: =Taxepunkter!F61 -> KÄ190TI52FV | G51: =Taxepunkter!G61 -> KÄ190TI52FV | H51: =Taxepunkter!H61 | ... L51: =Taxepunkter!L61 -> 0
A52: =Taxepunkter!A62 -> §2.2.4 | B52: =Taxepunkter!B62 -> Hämtningsavgift per år för flerbostadshus | C52: =Taxepunkter!C62 -> Kärl 190 l (tidningar och returpapper) | D52: =Taxepunkter!D62 -> Hämtning var 14:e dag | E52: =Taxepunkter!E62 -> st/år | F52: =Taxepunkter!F62 -> KÄ190TI26FV | G52: =Taxepunkter!G62 -> KÄ190TI26FV | H52: =Taxepunkter!H62 | ... L52: =Taxepunkter!L62 -> 0
A53: =Taxepunkter!A63 -> §2.2.4 | B53: =Taxepunkter!B63 -> Hämtningsavgift per år för flerbostadshus | C53: =Taxepunkter!C63 -> Kärl 190 l (tidningar och returpapper) | D53: =Taxepunkter!D63 -> Hämtning månadsvis | E53: =Taxepunkter!E63 -> st/år | F53: =Taxepunkter!F63 -> KÄ190TI12FV | G53: =Taxepunkter!G63 -> KÄ190TI12FV | H53: =Taxepunkter!H63 | ... L53: =Taxepunkter!L63 -> 0
A54: =Taxepunkter!A64 -> §2.2.4 | B54: =Taxepunkter!B64 -> Hämtningsavgift per år för flerbostadshus | C54: =Taxepunkter!C64 -> Kärl 370 l (tidningar och returpapper) | D54: =Taxepunkter!D64 -> Hämtning varje vecka | E54: =Taxepunkter!E64 -> st/år | F54: =Taxepunkter!F64 -> KÄ370TI52FV | G54: =Taxepunkter!G64 -> KÄ370TI52FV | H54: =Taxepunkter!H64 | ... L54: =Taxepunkter!L64 -> 0
A55: =Taxepunkter!A65 -> §2.2.4 | B55: =Taxepunkter!B65 -> Hämtningsavgift per år för flerbostadshus | C55: =Taxepunkter!C65 -> Kärl 370 l (tidningar och returpapper) | D55: =Taxepunkter!D65 -> Hämtning var 14:e dag | E55: =Taxepunkter!E65 -> st/år | F55: =Taxepunkter!F65 -> KÄ370TI26FV | G55: =Taxepunkter!G65 -> KÄ370TI26FV | H55: =Taxepunkter!H65 | ... L55: =Taxepunkter!L65 -> 0
A56: =Taxepunkter!A66 -> §2.2.4 | B56: =Taxepunkter!B66 -> Hämtningsavgift per år för flerbostadshus | C56: =Taxepunkter!C66 -> Kärl 370 l (tidningar och returpapper) | D56: =Taxepunkter!D66 -> Hämtning månadsvis | E56: =Taxepunkter!E66 -> st/år | F56: =Taxepunkter!F66 -> KÄ370TI12FV | G56: =Taxepunkter!G66 -> KÄ370TI12FV | H56: =Taxepunkter!H66 | ... L56: =Taxepunkter!L66 -> 0
...

Sheet Pivot Variant
A1: Intäkt per Paragraf och Variant
A3: Paragraf | B3: Variant | C3: Total intäkt (kr)
A4: §2.2.4 | B4: Hämtning Avgift per lägenhet | C4: =SUMIFS(Taxepunkter_Rådata!K:K,Taxepunkter_Rådata!A:A,"§2.2.4",Taxepunkter_Rådata!D:D,"Hämtning Avgift per lägenhet") -> 0
A5: §2.2.4 | B5: Hämtning Avgift per tömning | C5: =SUMIFS(Taxepunkter_Rådata!K:K,Taxepunkter_Rådata!A:A,"§2.2.4",Taxepunkter_Rådata!D:D,"Hämtning Avgift per tömning") -> 0
A6: §2.2.4 | B6: Hämtning månadsvis | C6: =SUMIFS(Taxepunkter_Rådata!K:K,Taxepunkter_Rådata!A:A,"§2.2.4",Taxepunkter_Rådata!D:D,"Hämtning månadsvis") -> 0
A7: §2.2.4 | B7: Hämtning var 14:e dag | C7: =SUMIFS(Taxepunkter_Rådata!K:K,Taxepunkter_Rådata!A:A,"§2.2.4",Taxepunkter_Rådata!D:D,"Hämtning var 14:e dag") -> 0
A8: §2.2.4 | B8: Hämtning varje vecka | C8: =SUMIFS(Taxepunkter_Rådata!K:K,Taxepunkter_Rådata!A:A,"§2.2.4",Taxepunkter_Rådata!D:D,"Hämtning varje vecka") -> 0
A9: §2.2.5 | B9: Hämtning Avgift per tömning | C9: =SUMIFS(Taxepunkter_Rådata!K:K,Taxepunkter_Rådata!A:A,"§2.2.5",Taxepunkter_Rådata!D:D,"Hämtning Avgift per tömning") -> 0
A10: §2.2.5 | B10: Hämtning månadsvis | C10: =SUMIFS(Taxepunkter_Rådata!K:K,Taxepunkter_Rådata!A:A,"§2.2.5",Taxepunkter_Rådata!D:D,"Hämtning månadsvis") -> 0
A11: §2.2.5 | B11: Hämtning var 14:e dag | C11: =SUMIFS(Taxepunkter_Rådata!K:K,Taxepunkter_Rådata!A:A,"§2.2.5",Taxepunkter_Rådata!D:D,"Hämtning var 14:e dag") -> 0
A12: §2.2.5 | B12: Hämtning varje vecka | C12: =SUMIFS(Taxepunkter_Rådata!K:K,Taxepunkter_Rådata!A:A,"§2.2.5",Taxepunkter_Rådata!D:D,"Hämtning varje vecka") -> 0
A13: §2.6.2 | B13: Över 100 kg | C13: =SUMIFS(Taxepunkter_Rådata!K:K,Taxepunkter_Rådata!A:A,"§2.6.2",Taxepunkter_Rådata!D:D,"Över 100 kg") -> 0
A14: §2.6.2 | B14: Över 40 kg | C14: =SUMIFS(Taxepunkter_Rådata!K:K,Taxepunkter_Rådata!A:A,"§2.6.2",Taxepunkter_Rådata!D:D,"Över 40 kg") -> 0
A15: §2.6.2 | B15: Över 60 kg | C15: =SUMIFS(Taxepunkter_Rådata!K:K,Taxepunkter_Rådata!A:A,"§2.6.2",Taxepunkter_Rådata!D:D,"Över 60 kg") -> 0
A16: §2.6.5 | B16: 140–240 liter | C16: =SUMIFS(Taxepunkter_Rådata!K:K,Taxepunkter_Rådata!A:A,"§2.6.5",Taxepunkter_Rådata!D:D,"140–240 liter") -> 0
A17: §2.6.5 | B17: 370–660 liter | C17: =SUMIFS(Taxepunkter_Rådata!K:K,Taxepunkter_Rådata!A:A,"§2.6.5",Taxepunkter_Rådata!D:D,"370–660 liter") -> 0
A18: §2.6.7 | B18: 1,5-10 | C18: =SUMIFS(Taxepunkter_Rådata!K:K,Taxepunkter_Rådata!A:A,"§2.6.7",Taxepunkter_Rådata!D:D,"1,5-10") -> 0
A19: §2.6.7 | B19: 10-20 | C19: =SUMIFS(Taxepunkter_Rådata!K:K,Taxepunkter_Rådata!A:A,"§2.6.7",Taxepunkter_Rådata!D:D,"10-20") -> 0
A20: §2.6.7 | B20: 20-30 | C20: =SUMIFS(Taxepunkter_Rådata!K:K,Taxepunkter_Rådata!A:A,"§2.6.7",Taxepunkter_Rådata!D:D,"20-30") -> 0
A21: §3.3 | B21: Inom 24 timmar | C21: =SUMIFS(Taxepunkter_Rådata!K:K,Taxepunkter_Rådata!A:A,"§3.3",Taxepunkter_Rådata!D:D,"Inom 24 timmar") -> 0
A22: §3.3 | B22: Inom 7 arbetsdagar | C22: =SUMIFS(Taxepunkter_Rådata!K:K,Taxepunkter_Rådata!A:A,"§3.3",Taxepunkter_Rådata!D:D,"Inom 7 arbetsdagar") -> 0
A23: §4.1 | B23: Inom 7 arbetsdagar | C23: =SUMIFS(Taxepunkter_Rådata!K:K,Taxepunkter_Rådata!A:A,"§4.1",Taxepunkter_Rådata!D:D,"Inom 7 arbetsdagar") -> 0
A24: §4.3 | B24: Inom 24 timmar | C24: =SUMIFS(Taxepunkter_Rådata!K:K,Taxepunkter_Rådata!A:A,"§4.3",Taxepunkter_Rådata!D:D,"Inom 24 timmar") -> 0
A25: §4.3 | B25: Inom 7 arbetsdagar | C25: =SUMIFS(Taxepunkter_Rådata!K:K,Taxepunkter_Rådata!A:A,"§4.3",Taxepunkter_Rådata!D:D,"Inom 7 arbetsdagar") -> 0
A26: §5.3 | B26: Inom 24 timmar | C26: =SUMIFS(Taxepunkter_Rådata!K:K,Taxepunkter_Rådata!A:A,"§5.3",Taxepunkter_Rådata!D:D,"Inom 24 timmar") -> 0
A27: §5.3 | B27: Inom 7 arbetsdagar | C27: =SUMIFS(Taxepunkter_Rådata!K:K,Taxepunkter_Rådata!A:A,"§5.3",Taxepunkter_Rådata!D:D,"Inom 7 arbetsdagar") -> 0
A28: §6 | B28: 1009 | C28: =SUMIFS(Taxepunkter_Rådata!K:K,Taxepunkter_Rådata!A:A,"§6",Taxepunkter_Rådata!D:D,"1009") -> 0
A29: §6 | B29: 1013 | C29: =SUMIFS(Taxepunkter_Rådata!K:K,Taxepunkter_Rådata!A:A,"§6",Taxepunkter_Rådata!D:D,"1013") -> 0
A30: §6 | B30: 1043 | C30: =SUMIFS(Taxepunkter_Rådata!K:K,Taxepunkter_Rådata!A:A,"§6",Taxepunkter_Rådata!D:D,"1043") -> 0
A31: §6 | B31: 1044 | C31: =SUMIFS(Taxepunkter_Rådata!K:K,Taxepunkter_Rådata!A:A,"§6",Taxepunkter_Rådata!D:D,"1044") -> 0
A32: §6 | B32: 1046 | C32: =SUMIFS(Taxepunkter_Rådata!K:K,Taxepunkter_Rådata!A:A,"§6",Taxepunkter_Rådata!D:D,"1046") -> 0
A33: §6 | B33: 1057 | C33: =SUMIFS(Taxepunkter_Rådata!K:K,Taxepunkter_Rådata!A:A,"§6",Taxepunkter_Rådata!D:D,"1057") -> 0
A34: §6 | B34: 1072 | C34: =SUMIFS(Taxepunkter_Rådata!K:K,Taxepunkter_Rådata!A:A,"§6",Taxepunkter_Rådata!D:D,"1072") -> 0
A35: §6 | B35: 12 | C35: =SUMIFS(Taxepunkter_Rådata!K:K,Taxepunkter_Rådata!A:A,"§6",Taxepunkter_Rådata!D:D,"12") -> 0
A36: §6 | B36: 1202 | C36: =SUMIFS(Taxepunkter_Rådata!K:K,Taxepunkter_Rådata!A:A,"§6",Taxepunkter_Rådata!D:D,"1202") -> 0
A37: §6 | B37: 1203 | C37: =SUMIFS(Taxepunkter_Rådata!K:K,Taxepunkter_Rådata!A:A,"§6",Taxepunkter_Rådata!D:D,"1203") -> 0
A38: §6 | B38: 1263 | C38: =SUMIFS(Taxepunkter_Rådata!K:K,Taxepunkter_Rådata!A:A,"§6",Taxepunkter_Rådata!D:D,"1263") -> 0
A39: §6 | B39: 1304 | C39: =SUMIFS(Taxepunkter_Rådata!K:K,Taxepunkter_Rådata!A:A,"§6",Taxepunkter_Rådata!D:D,"1304") -> 0
A40: §6 | B40: 1479 | C40: =SUMIFS(Taxepunkter_Rådata!K:K,Taxepunkter_Rådata!A:A,"§6",Taxepunkter_Rådata!D:D,"1479") -> 0
A41: §6 | B41: 1495 | C41: =SUMIFS(Taxepunkter_Rådata!K:K,Taxepunkter_Rådata!A:A,"§6",Taxepunkter_Rådata!D:D,"1495") -> 0
...

Sheet Pivot Paragraf
A1: Summering – total intäkt per paragraf
A3: Paragraf | B3: Total intäkt (kr)
A4: §2.1 | B4: =SUMIFS(Taxepunkter_Rådata!K:K,Taxepunkter_Rådata!A:A,"§2.1") -> 0
A5: §2.2.1 | B5: =SUMIFS(Taxepunkter_Rådata!K:K,Taxepunkter_Rådata!A:A,"§2.2.1") -> 0
A6: §2.2.2 | B6: =SUMIFS(Taxepunkter_Rådata!K:K,Taxepunkter_Rådata!A:A,"§2.2.2") -> 0
A7: §2.2.3 | B7: =SUMIFS(Taxepunkter_Rådata!K:K,Taxepunkter_Rådata!A:A,"§2.2.3") -> 0
A8: §2.2.4 | B8: =SUMIFS(Taxepunkter_Rådata!K:K,Taxepunkter_Rådata!A:A,"§2.2.4") -> 0
A9: §2.2.5 | B9: =SUMIFS(Taxepunkter_Rådata!K:K,Taxepunkter_Rådata!A:A,"§2.2.5") -> 0
A10: §2.3 | B10: =SUMIFS(Taxepunkter_Rådata!K:K,Taxepunkter_Rådata!A:A,"§2.3") -> 0
A11: §2.4 | B11: =SUMIFS(Taxepunkter_Rådata!K:K,Taxepunkter_Rådata!A:A,"§2.4") -> 0
A12: §2.5 | B12: =SUMIFS(Taxepunkter_Rådata!K:K,Taxepunkter_Rådata!A:A,"§2.5") -> 0
A13: §2.6.1 | B13: =SUMIFS(Taxepunkter_Rådata!K:K,Taxepunkter_Rådata!A:A,"§2.6.1") -> 0
A14: §2.6.2 | B14: =SUMIFS(Taxepunkter_Rådata!K:K,Taxepunkter_Rådata!A:A,"§2.6.2") -> 0
A15: §2.6.3 | B15: =SUMIFS(Taxepunkter_Rådata!K:K,Taxepunkter_Rådata!A:A,"§2.6.3") -> 0
A16: §2.6.4 | B16: =SUMIFS(Taxepunkter_Rådata!K:K,Taxepunkter_Rådata!A:A,"§2.6.4") -> 0
A17: §2.6.5 | B17: =SUMIFS(Taxepunkter_Rådata!K:K,Taxepunkter_Rådata!A:A,"§2.6.5") -> 0
A18: §2.6.6 | B18: =SUMIFS(Taxepunkter_Rådata!K:K,Taxepunkter_Rådata!A:A,"§2.6.6") -> 0
A19: §2.6.7 | B19: =SUMIFS(Taxepunkter_Rådata!K:K,Taxepunkter_Rådata!A:A,"§2.6.7") -> 0
A20: §2.6.8 | B20: =SUMIFS(Taxepunkter_Rådata!K:K,Taxepunkter_Rådata!A:A,"§2.6.8") -> 0
A21: §2.6.9 | B21: =SUMIFS(Taxepunkter_Rådata!K:K,Taxepunkter_Rådata!A:A,"§2.6.9") -> 0
A22: §2.7.1 | B22: =SUMIFS(Taxepunkter_Rådata!K:K,Taxepunkter_Rådata!A:A,"§2.7.1") -> 0
A23: §2.7.2 | B23: =SUMIFS(Taxepunkter_Rådata!K:K,Taxepunkter_Rådata!A:A,"§2.7.2") -> 0
A24: §2.7.3 | B24: =SUMIFS(Taxepunkter_Rådata!K:K,Taxepunkter_Rådata!A:A,"§2.7.3") -> 0
A25: §2.7.4 | B25: =SUMIFS(Taxepunkter_Rådata!K:K,Taxepunkter_Rådata!A:A,"§2.7.4") -> 0
A26: §3.1 | B26: =SUMIFS(Taxepunkter_Rådata!K:K,Taxepunkter_Rådata!A:A,"§3.1") -> 0
A27: §3.2 | B27: =SUMIFS(Taxepunkter_Rådata!K:K,Taxepunkter_Rådata!A:A,"§3.2") -> 0
A28: §3.3 | B28: =SUMIFS(Taxepunkter_Rådata!K:K,Taxepunkter_Rådata!A:A,"§3.3") -> 0
A29: §4.1 | B29: =SUMIFS(Taxepunkter_Rådata!K:K,Taxepunkter_Rådata!A:A,"§4.1") -> 0
A30: §4.2 | B30: =SUMIFS(Taxepunkter_Rådata!K:K,Taxepunkter_Rådata!A:A,"§4.2") -> 0
A31: §4.3 | B31: =SUMIFS(Taxepunkter_Rådata!K:K,Taxepunkter_Rådata!A:A,"§4.3") -> 0
A32: §5.1 | B32: =SUMIFS(Taxepunkter_Rådata!K:K,Taxepunkter_Rådata!A:A,"§5.1") -> 0
A33: §5.2 | B33: =SUMIFS(Taxepunkter_Rådata!K:K,Taxepunkter_Rådata!A:A,"§5.2") -> 0
A34: §5.3 | B34: =SUMIFS(Taxepunkter_Rådata!K:K,Taxepunkter_Rådata!A:A,"§5.3") -> 0
A35: §6 | B35: =SUMIFS(Taxepunkter_Rådata!K:K,Taxepunkter_Rådata!A:A,"§6") -> 0

Sheet Pivot Kapitel
A1: Summering – total intäkt per kapitel
A3: Kapitel | B3: Total intäkt (kr)
A4: 2 | B4: =SUMIFS(Taxepunkter_Rådata!K:K,Taxepunkter_Rådata!A:A,"§2*") -> 0
A5: 3 | B5: =SUMIFS(Taxepunkter_Rådata!K:K,Taxepunkter_Rådata!A:A,"§3*") -> 0
A6: 4 | B6: =SUMIFS(Taxepunkter_Rådata!K:K,Taxepunkter_Rådata!A:A,"§4*") -> 0
A7: 5 | B7: =SUMIFS(Taxepunkter_Rådata!K:K,Taxepunkter_Rådata!A:A,"§5*") -> 0
A8: 6 | B8: =SUMIFS(Taxepunkter_Rådata!K:K,Taxepunkter_Rådata!A:A,"§6*") -> 0

Sheet Diagram Intäkt
A1: Diagram – intäkt per paragraf

Sheet Kontroller
A1: Kontroller – datakvalitet
A3: Kontroll | B3: Resultat | C3: Status
A4: Antal rader (rådata) | B4: =COUNTA(Taxepunkter_Rådata!A:A)-1 -> 291 | C4: =IF(B4>0,"OK","VARNING") -> OK
A5: Saknade priser (tomma) | B5: =COUNTIF(Taxepunkter_Rådata!J:J,"")-1 -> 1048551 | C5: =IF(B5=0,"OK","VARNING") -> VARNING
A6: Andel rader med ifyllt pris | B6: =IF(B4=0,"",1-(B5/B4)) -> -3602.268 | C6: =IF(B6=1,"OK","VARNING") -> VARNING
A7: Rader med Antal > 0 men saknar pris | B7: =COUNTIFS(Taxepunkter_Rådata!I:I,">0",Taxepunkter_Rådata!J:J,"") -> 0 | C7: =IF(B7=0,"OK","VARNING") -> OK
A8: Rader med Pris ifyllt men Antal saknas | B8: =COUNTIFS(Taxepunkter_Rådata!J:J,"<>",Taxepunkter_Rådata!I:I,"") -> 268 | C8: =IF(B8=0,"OK","VARNING") -> VARNING

Sheet Taxa_från_edp
A1: intRecnum | B1: strTaxekod | C1: strTaxebenamning | D1: strProdukt | E1: strDelProdukt | F1: bytDelradnr | G1: strFaktor | H1: strTaxedelAvser | I1: strEntreprenorkod | J1: strRenhDistrKod | K1: curNuvarandePris | L1: datNuvarandePrisDatum | M1: bolPrisPerTomning | N1: strAvvikandeFormel | O1: bolPriserInklMoms | P1: bytMomskod | Q1: strFormel
A2: 1689 | B2: 140MAT | C2: 140L kärl, viktavgift matavfall | D2: RENH | E2: HUSH | F2: 1 | G2: KVAN | H2: 140L kärl - viktavgift matavfall | K2: 2 | L2: 44927 | M2: 0 | O2: - | P2: 1 | Q2: VIKG,MAX60
A3: 1690 | B3: 140MAT | C3: 140L kärl, viktavgift matavfall | D3: RENH | E3: HUSH | F3: 2 | G3: KVAN | H3: Överviktsavgift för vikt över 60 kg, matavfall | K3: 3.68 | L3: 44927 | M3: 0 | O3: - | P3: 1 | Q3: VIKG-60,MIN0
A4: 1693 | B4: 370REST | C4: 140-370L kärl, viktavgift restavfall | D4: RENH | E4: HUSH | F4: 1 | G4: KVAN | H4: 140-370L kärl - viktavgift restavfall | K4: 4 | L4: 44927 | M4: 0 | O4: - | P4: 1 | Q4: VIKG,MAX60
A5: 1694 | B5: 370REST | C5: 140-370L kärl, viktavgift restavfall | D5: RENH | E5: HUSH | F5: 2 | G5: KVAN | H5: Överviktsavgift för vikt över 60 kg, restavfall | K5: 7.36 | L5: 44927 | M5: 0 | O5: - | P5: 1 | Q5: VIKG-60,MIN0
A6: 1695 | B6: 660REST | C6: 660L kärl, viktavgift restavfall | D6: RENH | E6: HUSH | F6: 1 | G6: KVAN | H6: 660L kärl - viktavgift restavfall | K6: 4 | L6: 44927 | M6: 0 | O6: - | P6: 1 | Q6: VIKG,MAX100
A7: 1696 | B7: 660REST | C7: 660L kärl, viktavgift restavfall | D7: RENH | E7: HUSH | F7: 2 | G7: KVAN | H7: Överviktsavgift för vikt över 100 kg, restavfall | K7: 7.36 | L7: 44927 | M7: 0 | O7: - | P7: 1 | Q7: VIKG-100,MIN0
A8: 1626 | B8: BDT03SLBUD | C8: BDT 0-3 m³, slam. Budning | D8: RENH | E8: SLAM | F8: 1 | G8: ÅRKV | H8: BDT 0-3 m³, slam. Budning | K8: 0 | L8: 44927 | M8: 0 | O8: - | P8: 1 | Q8: 0
A9: 1610 | B9: BDT03SLORD | C9: BDT 0-3 m³, slam. Ordinarie tur | D9: RENH | E9: SLAM | F9: 1 | G9: ÅRKV | H9: BDT 0-3 m³, slam. Ordinarie tur | K9: 0 | L9: 44927 | M9: 0 | O9: - | P9: 1 | Q9: 0
A10: 1625 | B10: BDTÖ3SLBUD | C10: BDT över 3 m³, slam. Budning | D10: RENH | E10: SLAM | F10: 1 | G10: ÅRKV | H10: BDT över 3 m³, slam. Budning | K10: 0 | L10: 44927 | M10: 0 | O10: - | P10: 1 | Q10: 0
A11: 1611 | B11: BDTÖ3SLORD | C11: BDT över 3 m³, slam. Ordinarie tur | D11: RENH | E11: SLAM | F11: 1 | G11: ÅRKV | H11: BDT över 3 m³, slam. Ordinarie tur | K11: 0 | L11: 44927 | M11: 0 | O11: - | P11: 1 | Q11: 0
A12: 1613 | B12: BRN03SLBUD | C12: Brunn 0-3 m³, slam. Budning | D12: RENH | E12: SLAM | F12: 1 | G12: ÅRKV | H12: Brunn 0-3 m³, slam. Budning | K12: 0 | L12: 44927 | M12: 0 | O12: X | P12: 1 | Q12: 0
A13: 1598 | B13: BRN03SLORD | C13: Brunn 0-3 m³, slam. Ordinarie tur | D13: RENH | E13: SLAM | F13: 1 | G13: ÅRKV | H13: Brunn 0-3 m³, slam. Ordinarie tur | K13: 0 | L13: 44927 | M13: 0 | O13: - | P13: 1 | Q13: 0
... A86: 1814 | B86: EVEKÄ660RE | C86: Evenemangskärl 660 L, restavfall | D86: RENH | E86: HUSH | F86: 1 | G86: KVAN | H86: Evenemangskärl 660 L, restavfall | K86: 184 | L86: 45292 | M86: 0 | O86: - | P86: 1 | Q86: ANTB
A87: 1652 | B87: EXTMÄTVS | C87: Extra mätställe, vatten/spillvatten | D87: VA | E87: VA | F87: 1 | G87: ÅRPR | H87: Fast avgift, vatten/spillvatten | K87: 656 | L87: 45292 | M87: 0 | O87: - | P87: 1
A88: 1793 | B88: FARLIGTBUD | C88: Budning av farligt avfall per m³ | D88: RENH | E88: HUSH | F88: 1 | G88: KVAN | H88: Budning av farligt avfall per m³ | K88: 3840 | L88: 45292 | M88: 0 | O88: - | P88: 1 | Q88: ANTL
A89: 1863 | B89: FASTOLJEAVFALL | C89: Fast oljeavfall | D89: RENH | E89: ÅVC | F89: 1 | G89: KVAN | H89: Fast oljeavfall | K89: 25 | L89: 45292 | M89: 0 | O89: - | P89: 1 | Q89: VIKG
A90: 1840 | B90: FASTSODA | C90: Fast soda i små emballage | D90: RENH | E90: ÅVC | F90: 1 | G90: KVAN | H90: Fast soda i små emballage | K90: 50 | L90: 45292 | M90: 0 | O90: - | P90: 1 | Q90: VIKG
A91: 1938 | B91: FOBFRI | C91: Nyckelfob mat- och restavfall fritidshus (engångs) | D91: RENH | E91: HUSH | F91: 1 | G91: KVAN | H91: Avser fysisk nyckel för mat-och restavfall - Engångskostnad | K91: 1200 | L91: 45292 | M91: 0 | O91: - | P91: 1 | Q91: ANTL
A92: 1723 | B92: FOSTÖM1000 | C92: Tömning och behandling fosforfilter 500-1000 kg | D92: RENH | E92: SLAM | F92: 1 | G92: KVAN | H92: Tömning och behandling fosforfilter 500-1000 kg | K92: 3840 | L92: 45292 | M92: 0 | O92: - | P92: 1 | Q92: ANTL
A93: 1724 | B93: FOSTÖM500 | C93: Tömning och behandling fosforfilter under 500 kg | D93: RENH | E93: SLAM | F93: 1 | G93: KVAN | H93: Tömning och behandling fosforfilter under 500 kg | K93: 2880 | L93: 45292 | M93: 0 | O93: - | P93: 1 | Q93: ANTL
A94: 1841 | B94: FOTOKEM | C94: Fotokemikalier | D94: RENH | E94: ÅVC | F94: 1 | G94: KVAN | H94: Fotokemikalier | K94: 35 | L94: 45292 | M94: 0 | O94: - | P94: 1 | Q94: VIKG
A95: 1760 | B95: FRAMKÖRKOM | C95: Framkörningsavgift, hämtning av kommunalt avfall | D95: RENH | E95: HUSH | F95: 1 | G95: KVAN | H95: Framkörningsavgift, hämtning av kommunalt avfall | K95: 1600 | L95: 45292 | M95: 0 | O95: - | P95: 1 | Q95: ANTL
A96: 1845 | B96: FÄRGEJKONS | C96: Färg ej konsumentförpackat | D96: RENH | E96: ÅVC | F96: 1 | G96: KVAN | H96: Färg ej konsumentförpackat | K96: 25 | L96: 45292 | M96: 0 | O96: - | P96: 1 | Q96: VIKG
A97: 1843 | B97: FÄRGLÖSNING | C97: Färg/lackavfall/lim lösningsbaserat | D97: RENH | E97: ÅVC | F97: 1 | G97: KVAN | H97: Färg/lackavfall/lim lösningsbaserat | K97: 10 | L97: 45292 | M97: 0 | O97: - | P97: 1 | Q97: VIKG
A98: 1844 | B98: FÄRGVATTEN | C98: Färg/lackavfall/lim vattenbaserat | D98: RENH | E98: ÅVC | F98: 1 | G98: KVAN | H98: Färg/lackavfall/lim vattenbaserat | K98: 10 | L98: 45292 | M98: 0 | O98: - | P98: 1 | Q98: VIKG
A99: 1851 | B99: GASOL | C99: Gasol, blå programmet (kräver speciell transport) | D99: RENH | E99: ÅVC | F99: 1 | G99: KVAN | H99: Gasol, blå programmet | K99: 500 | L99: 45292 | M99: 0 | O99: - | P99: 1 | Q99: VIKG
... A101: 1748 | B101: GEMKÄFRI | C101: Gemensam uppsamlingsplats med eget kärl, fritidshus | D101: RENH | E101: HUSH | F101: 2 | G101: KVAN | H101: Viktavgift rest- matavfall kr/kg | K101: 0 | L101: 45292 | M101: 0 | O101: - | P101: 1 | Q101: VIKG
A102: 1935 | B102: GEMUPPEXTRAFRI | C102: Extra mobilnyckel till Gemensam uppsamlingsplats, fritidshus | D102: RENH | E102: HUSH | F102: 1 | G102: ÅRPR | H102: Extra Mobilnyckel till ÅVS | K102: 80 | L102: 45292 | M102: 0 | O102: - | P102: 1
A103: 1934 | B103: GEMUPPFRINYCKEL | C103: Nyckelfob till Gemensam uppsamlingsplats, fritidshus | D103: RENH | E103: HUSH | F103: 1 | G103: TEXT | H103: Nyckelfob, engångskostnad | K103: 1200 | L103: 45292 | M103: 0 | O103: - | P103: 1
A104: 1970 | B104: GEMUPPFÖRPFLB | C104: Gemensam uppsamlingsplats Förpackning, Flerbostadshus | D104: RENH | E104: HUSH | F104: 1 | G104: ÅRKV | H104: Gemensam uppsamlingsplats Förpackning, Flerbostadshus | K104: 0 | L104: 45292 | M104: 0 | O104: - | P104: 1 | Q104: FAST
A105: 1936 | B105: GEMUPPORDFRI | C105: Mobilnyckel Gemensam uppsamlingsplats, fritidshus | D105: RENH | E105: HUSH | F105: 1 | G105: ÅRKV | H105: Mobilnyckel Gemensam uppsamlingsplats, mat- och restavfall | K105: 0 | L105: 45292 | M105: 0 | O105: - | P105: 1 | Q105: FAST
A106: 1770 | B106: GRBUD | C106: Budad hämtning, grovavfall. Pris per m³ | D106: RENH | E106: HUSH | F106: 1 | G106: KVAN | H106: Budad hämtning, grovavfall. Pris per m³ | K106: 480 | L106: 45292 | M106: 0 | O106: - | P106: 1 | Q106: KBMÖ
A107: 1792 | B107: GROVBUD | C107: Budning av grovavfall per m³ | D107: RENH | E107: HUSH | F107: 1 | G107: KVAN | H107: Budning av grovavfall per m³ | K107: 480 | L107: 45292 | M107: 0 | O107: - | P107: 1 | Q107: KBMÖ
A108: 1749 | B108: GRUNDFLB | C108: Grundavgift, del i flerbostadshus | D108: RENH | E108: HUSH | F108: 1 | G108: ÅRKV | H108: Grundavgift, del i flerbostadshus | K108: 640 | L108: 45292 | M108: 0 | O108: - | P108: 1 | Q108: GRUN
A109: 1807 | B109: GRUNDFRI | C109: Grundavgift, fritidshus | D109: RENH | E109: HUSH | F109: 1 | G109: ÅRKV | H109: Grundavgift, fritidshus | K109: 1000 | L109: 45292 | M109: 0 | O109: - | P109: 1 | Q109: GRUN
A110: 1752 | B110: GRUNDVHT | C110: Grundavgift, verksamheter | D110: RENH | E110: HUSH | F110: 1 | G110: ÅRKV | H110: Grundavgift, verksamheter | K110: 1000 | L110: 45292 | M110: 0 | O110: - | P110: 1 | Q110: GRUN
A111: 1850 | B111: HALONGAS | C111: Halon gaser (kräver speciell transport) | D111: RENH | E111: ÅVC | F111: 1 | G111: KVAN | H111: Halon gaser | K111: 160 | L111: 45292 | M111: 0 | O111: - | P111: 1 | Q111: VIKG
A112: 1848 | B112: HYDRAULSLANG | C112: Hydraulslang | D112: RENH | E112: ÅVC | F112: 1 | G112: KVAN | H112: Hydraulslang | K112: 15 | L112: 45292 | M112: 0 | O112: - | P112: 1 | Q112: VIKG
A113: 1860 | B113: HÄRDARE | C113: Härdare | D113: RENH | E113: ÅVC | F113: 1 | G113: KVAN | H113: Härdare | K113: 60 | L113: 45292 | M113: 0 | O113: - | P113: 1 | Q113: VIKG
...

Sheet Taxa_till_edp
A1: intRecnum | B1: strTaxekod | C1: strTaxebenamning | D1: strProdukt | E1: strDelProdukt | F1: bytDelradnr | G1: strFaktor | H1: strTaxedelAvser | I1: strEntreprenorkod | J1: strRenhDistrKod | K1: curNuvarandePris | L1: datNuvarandePrisDatum | M1: bolPrisPerTomning | N1: strAvvikandeFormel | O1: bolPriserInklMoms | P1: bytMomskod | Q1: strFormel

Sheet Sammanställning
B1: Sammanställning – total intäkt per paragraf
B3: Paragraf | C3: Paragrafnamn | D3: Total intäkt (kr)
B4: §2.1 | C4: Grundavgift | D4: =SUMIF(Taxepunkter!A:A,"§2.1",Taxepunkter!I:I) -> 0
B5: §2.2.1 | C5: Hämtningsavgift per år för en- och tvåbostadshus | D5: =SUMIF(Taxepunkter!A:A,"§2.2.1",Taxepunkter!I:I) -> 0
B6: §2.2.2 | C6: Hämtningsavgift per år för fritidshus | D6: =SUMIF(Taxepunkter!A:A,"§2.2.2",Taxepunkter!I:I) -> 0
B7: §2.2.3 | C7: Hämtningsavgift per år gemensam uppsamlingsplats för hämtningsområde X | D7: =SUMIF(Taxepunkter!A:A,"§2.2.3",Taxepunkter!I:I) -> 0
B8: §2.2.4 | C8: Hämtningsavgift per år för flerbostadshus | D8: =SUMIF(Taxepunkter!A:A,"§2.2.4",Taxepunkter!I:I) -> 0
B9: §2.2.5 | C9: Hämtningsavgift per år för verksamheter | D9: =SUMIF(Taxepunkter!A:A,"§2.2.5",Taxepunkter!I:I) -> 0
B10: §2.3 | C10: Rörlig avgift (gäller ej gemensam uppsamlingsplats) | D10: =SUMIF(Taxepunkter!A:A,"§2.3",Taxepunkter!I:I) -> 0
B11: §2.4 | C11: Betalsäck och akutsäck | D11: =SUMIF(Taxepunkter!A:A,"§2.4",Taxepunkter!I:I) -> 0
B12: §2.5 | C12: Matavfallspåsar | D12: =SUMIF(Taxepunkter!A:A,"§2.5",Taxepunkter!I:I) -> 0
B13: §2.6.1 | C13: Fakturaavgift | D13: =SUMIF(Taxepunkter!A:A,"§2.6.1",Taxepunkter!I:I) -> 0
B14: §2.6.2 | C14: Överviktsavgift kärl | D14: =SUMIF(Taxepunkter!A:A,"§2.6.2",Taxepunkter!I:I) -> 0
B15: §2.6.3 | C15: Överfullt kärl/bottentömmande behållare | D15: =SUMIF(Taxepunkter!A:A,"§2.6.3",Taxepunkter!I:I) -> 0
B16: §2.6.4 | C16: Byte av trasigt kärl | D16: =SUMIF(Taxepunkter!A:A,"§2.6.4",Taxepunkter!I:I) -> 0
B17: §2.6.5 | C17: Byte av abonnemang | D17: =SUMIF(Taxepunkter!A:A,"§2.6.5",Taxepunkter!I:I) -> 0
